<?xml version="1.0" encoding="utf-8"?>
<!-- This URDF was automatically created by SolidWorks to URDF Exporter! Originally created by Stephen Brawner (brawner@gmail.com) 
     Commit Version:   Build Version: 1.6.9177.32434
     For more information, please see http://wiki.ros.org/sw_urdf_exporter -->
<robot
  name="gimbalrotor">
  <link
    name="main_body">
    <inertial>
      <origin
        xyz="-0.00202460418348044 -0.000510481706680737 -0.0123651551887967"
        rpy="0 0 0" />
      <mass
        value="1.40071559053294" />
      <inertia
        ixx="0.00167259281385339"
        ixy="-1.88191851673578E-07"
        ixz="7.17787328777675E-07"
        iyy="0.00167984573863287"
        iyz="4.03619596691479E-08"
        izz="0.00304193991451692" />
    </inertial>
    <visual>
      <origin
        xyz="0 0 0.0175"
        rpy="3.14159265358979 0 2.35619449019236" />
      <geometry>
        <mesh
          filename="package://gimbalrotor/meshes/main_body.3dxml" />
      </geometry>
      <material
        name="">
        <color
          rgba="0.109803921568627 0.109803921568627 0.109803921568627 1" />
      </material>
    </visual>
    <collision>
      <origin
        xyz="0 0 0.0175"
        rpy="3.14159265358979 0 2.35619449019236" />
      <geometry>
        <mesh
          filename="package://gimbalrotor/meshes/main_body.3dxml" />
      </geometry>
    </collision>
  </link>
  <link
    name="gimbal1_link">
    <inertial>
      <origin
        xyz="-0.00926567494919711 1.9703972765894E-06 0.0128616849753725"
        rpy="0 0 0" />
      <mass
        value="0.243868409767181" />
      <inertia
        ixx="4.70366622152039E-05"
        ixy="-5.23334464430229E-09"
        ixz="-4.58510270196035E-07"
        iyy="4.49457729860046E-05"
        iyz="-2.62506744960952E-09"
        izz="4.59133399019853E-05" />
    </inertial>
    <visual>
      <origin
        xyz="-0.3155 2.58957711778232E-16 0.0174999999999999"
        rpy="-3.14159265358979 1.1740359245238E-15 -1.57079632679489" />
      <geometry>
        <mesh
          filename="package://gimbalrotor/meshes/gimbal1_link.3dxml" />
      </geometry>
      <material
        name="">
        <color
          rgba="0.752941176470588 0.752941176470588 0.752941176470588 1" />
      </material>
    </visual>
    <collision>
      <origin
        xyz="-0.3155 2.58957711778232E-16 0.0174999999999999"
        rpy="-3.14159265358979 1.1740359245238E-15 -1.57079632679489" />
      <geometry>
        <mesh
          filename="package://gimbalrotor/meshes/gimbal1_link.3dxml" />
      </geometry>
    </collision>
  </link>
  <joint
    name="gimbal1"
    type="revolute">
    <origin
      xyz="-0.22309 -0.22309 0"
      rpy="0 0 -2.3562" />
    <parent
      link="main_body" />
    <child
      link="gimbal1_link" />
    <axis
      xyz="1 0 0" />
    <limit
      lower="0"
      upper="0"
      effort="0"
      velocity="0" />
  </joint>
  <link
    name="thrust1">
    <inertial>
      <origin
        xyz="-5.83353443328605E-09 6.00431360659234E-10 0.00419839092547531"
        rpy="0 0 0" />
      <mass
        value="0.011379798689915" />
      <inertia
        ixx="8.74001997923959E-05"
        ixy="-4.12766506878745E-06"
        ixz="-1.94275247125274E-13"
        iyy="6.72594264513234E-07"
        iyz="8.34517033335333E-15"
        izz="8.79093348597008E-05" />
    </inertial>
    <visual>
      <origin
        xyz="-0.3155 -1.34369381138595E-16 -0.0409999999999993"
        rpy="-3.14159265358979 1.1740359245238E-15 -1.57079632679489" />
      <geometry>
        <mesh
          filename="package://gimbalrotor/meshes/thrust1.3dxml" />
      </geometry>
      <material
        name="">
        <color
          rgba="0.501960784313725 0.501960784313725 0.501960784313725 1" />
      </material>
    </visual>
    <collision>
      <origin
        xyz="-0.3155 -1.34369381138595E-16 -0.0409999999999993"
        rpy="-3.14159265358979 1.1740359245238E-15 -1.57079632679489" />
      <geometry>
        <mesh
          filename="package://gimbalrotor/meshes/thrust1.3dxml" />
      </geometry>
    </collision>
  </link>
  <joint
    name="rotor1"
    type="continuous">
    <origin
      xyz="0 0 0.0585"
      rpy="0 0 0" />
    <parent
      link="gimbal1_link" />
    <child
      link="thrust1" />
    <axis
      xyz="0 0 -1" />
  </joint>
  <link
    name="gimbal2_link">
    <inertial>
      <origin
        xyz="-0.00926567494919767 1.97039727626247E-06 0.0128616849753725"
        rpy="0 0 0" />
      <mass
        value="0.243868409767181" />
      <inertia
        ixx="4.70366622152039E-05"
        ixy="-5.23334464430243E-09"
        ixz="-4.58510270196032E-07"
        iyy="4.49457729860046E-05"
        iyz="-2.62506744960964E-09"
        izz="4.59133399019854E-05" />
    </inertial>
    <visual>
      <origin
        xyz="-0.3155 -6.77742606418939E-17 0.0174999999999999"
        rpy="3.14159265358979 2.11841642290955E-16 -3.14159265358979" />
      <geometry>
        <mesh
          filename="package://gimbalrotor/meshes/gimbal2_link.3dxml" />
      </geometry>
      <material
        name="">
        <color
          rgba="0.898039215686275 0.917647058823529 0.929411764705882 1" />
      </material>
    </visual>
    <collision>
      <origin
        xyz="-0.3155 -6.77742606418939E-17 0.0174999999999999"
        rpy="3.14159265358979 2.11841642290955E-16 -3.14159265358979" />
      <geometry>
        <mesh
          filename="package://gimbalrotor/meshes/gimbal2_link.3dxml" />
      </geometry>
    </collision>
  </link>
  <joint
    name="gimbal2"
    type="revolute">
    <origin
      xyz="0.22309 -0.22309 0"
      rpy="0 0 -0.7854" />
    <parent
      link="main_body" />
    <child
      link="gimbal2_link" />
    <axis
      xyz="1 0 0" />
    <limit
      lower="0"
      upper="0"
      effort="0"
      velocity="0" />
  </joint>
  <link
    name="thrust2">
    <inertial>
      <origin
        xyz="-2.56972954026935E-09 3.06808817088874E-09 0.00419843813014376"
        rpy="0 0 0" />
      <mass
        value="0.0113800668107397" />
      <inertia
        ixx="8.73993574758916E-05"
        ixy="4.12756893234927E-06"
        ixz="-1.16071744831874E-13"
        iyy="6.7258088785491E-07"
        iyz="1.27017867936525E-13"
        izz="8.79084828385424E-05" />
    </inertial>
    <visual>
      <origin
        xyz="-0.3155 -1.34420668641789E-16 -0.0409999999999993"
        rpy="3.14159265358979 2.11841642290955E-16 -3.14159265358979" />
      <geometry>
        <mesh
          filename="package://gimbalrotor/meshes/thrust2.3dxml" />
      </geometry>
      <material
        name="">
        <color
          rgba="0.501960784313725 0.501960784313725 0.501960784313725 1" />
      </material>
    </visual>
    <collision>
      <origin
        xyz="-0.3155 -1.34420668641789E-16 -0.0409999999999993"
        rpy="3.14159265358979 2.11841642290955E-16 -3.14159265358979" />
      <geometry>
        <mesh
          filename="package://gimbalrotor/meshes/thrust2.3dxml" />
      </geometry>
    </collision>
  </link>
  <joint
    name="rotor2"
    type="continuous">
    <origin
      xyz="0 0 0.0585"
      rpy="0 0 0" />
    <parent
      link="gimbal2_link" />
    <child
      link="thrust2" />
    <axis
      xyz="0 0 1" />
  </joint>
  <link
    name="gimbal3_link">
    <inertial>
      <origin
        xyz="-0.00926567494919739 1.97039727626326E-06 0.0128616849753725"
        rpy="0 0 0" />
      <mass
        value="0.243868409767181" />
      <inertia
        ixx="4.70366622152039E-05"
        ixy="-5.23334464430207E-09"
        ixz="-4.58510270196014E-07"
        iyy="4.49457729860046E-05"
        iyz="-2.62506744960844E-09"
        izz="4.59133399019853E-05" />
    </inertial>
    <visual>
      <origin
        xyz="-0.3155 -6.79066863685113E-17 0.0174999999999999"
        rpy="3.14159265358979 -1.1740359245238E-15 1.5707963267949" />
      <geometry>
        <mesh
          filename="package://gimbalrotor/meshes/gimbal3_link.3dxml" />
      </geometry>
      <material
        name="">
        <color
          rgba="0.752941176470588 0.752941176470588 0.752941176470588 1" />
      </material>
    </visual>
    <collision>
      <origin
        xyz="-0.3155 -6.79066863685113E-17 0.0174999999999999"
        rpy="3.14159265358979 -1.1740359245238E-15 1.5707963267949" />
      <geometry>
        <mesh
          filename="package://gimbalrotor/meshes/gimbal3_link.3dxml" />
      </geometry>
    </collision>
  </link>
  <joint
    name="gimbal3"
    type="revolute">
    <origin
      xyz="0.22309 0.22309 0"
      rpy="0 0 0.7854" />
    <parent
      link="main_body" />
    <child
      link="gimbal3_link" />
    <axis
      xyz="1 0 0" />
    <limit
      lower="0"
      upper="0"
      effort="0"
      velocity="0" />
  </joint>
  <link
    name="thrust3">
    <inertial>
      <origin
        xyz="-5.83425141531535E-09 6.01800406659052E-10 0.00419839092622981"
        rpy="0 0 0" />
      <mass
        value="0.0113797986875362" />
      <inertia
        ixx="8.74001997906142E-05"
        ixy="-4.12766506892759E-06"
        ixz="-1.9423641282498E-13"
        iyy="6.72594264594888E-07"
        iyz="8.63468898765394E-15"
        izz="8.79093348579925E-05" />
    </inertial>
    <visual>
      <origin
        xyz="-0.3155 -1.34841394351049E-16 -0.0409999999999993"
        rpy="3.14159265358979 -1.1740359245238E-15 1.5707963267949" />
      <geometry>
        <mesh
          filename="package://gimbalrotor/meshes/thrust3.3dxml" />
      </geometry>
      <material
        name="">
        <color
          rgba="0.501960784313725 0.501960784313725 0.501960784313725 1" />
      </material>
    </visual>
    <collision>
      <origin
        xyz="-0.3155 -1.34841394351049E-16 -0.0409999999999993"
        rpy="3.14159265358979 -1.1740359245238E-15 1.5707963267949" />
      <geometry>
        <mesh
          filename="package://gimbalrotor/meshes/thrust3.3dxml" />
      </geometry>
    </collision>
  </link>
  <joint
    name="rotor3"
    type="continuous">
    <origin
      xyz="0 0 0.0585"
      rpy="0 0 0" />
    <parent
      link="gimbal3_link" />
    <child
      link="thrust3" />
    <axis
      xyz="0 0 -1" />
  </joint>
  <link
    name="gimbal4_link">
    <inertial>
      <origin
        xyz="-0.00926567494919772 1.97039712329184E-06 0.0128616849753724"
        rpy="0 0 0" />
      <mass
        value="0.243868409767181" />
      <inertia
        ixx="4.70366622152039E-05"
        ixy="-5.23334464430183E-09"
        ixz="-4.5851027019603E-07"
        iyy="4.49457729860046E-05"
        iyz="-2.62506744960961E-09"
        izz="4.59133399019854E-05" />
    </inertial>
    <visual>
      <origin
        xyz="-0.3155 -6.79066863685114E-17 0.0174999999999999"
        rpy="-3.14159265358979 -2.11841642290947E-16 2.86097492828976E-16" />
      <geometry>
        <mesh
          filename="package://gimbalrotor/meshes/gimbal4_link.3dxml" />
      </geometry>
      <material
        name="">
        <color
          rgba="0.898039215686275 0.917647058823529 0.929411764705882 1" />
      </material>
    </visual>
    <collision>
      <origin
        xyz="-0.3155 -6.79066863685114E-17 0.0174999999999999"
        rpy="-3.14159265358979 -2.11841642290947E-16 2.86097492828976E-16" />
      <geometry>
        <mesh
          filename="package://gimbalrotor/meshes/gimbal4_link.3dxml" />
      </geometry>
    </collision>
  </link>
  <joint
    name="gimbal4"
    type="revolute">
    <origin
      xyz="-0.22309 0.22309 0"
      rpy="0 0 2.3562" />
    <parent
      link="main_body" />
    <child
      link="gimbal4_link" />
    <axis
      xyz="1 0 0" />
    <limit
      lower="0"
      upper="0"
      effort="0"
      velocity="0" />
  </joint>
  <link
    name="thrust4">
    <inertial>
      <origin
        xyz="-2.5501448175369E-09 3.18832430420899E-09 0.00419843814009516"
        rpy="0 0 0" />
      <mass
        value="0.0113800667770834" />
      <inertia
        ixx="8.73993574510469E-05"
        ixy="4.12756894375054E-06"
        ixz="-1.15301708553968E-13"
        iyy="6.7258088604331E-07"
        iyz="1.31787422616219E-13"
        izz="8.79084828126607E-05" />
    </inertial>
    <visual>
      <origin
        xyz="-0.3155 -1.34394758322319E-16 -0.0409999999999993"
        rpy="-3.14159265358979 -2.11841642290947E-16 2.86097492828976E-16" />
      <geometry>
        <mesh
          filename="package://gimbalrotor/meshes/thrust4.3dxml" />
      </geometry>
      <material
        name="">
        <color
          rgba="0.501960784313725 0.501960784313725 0.501960784313725 1" />
      </material>
    </visual>
    <collision>
      <origin
        xyz="-0.3155 -1.34394758322319E-16 -0.0409999999999993"
        rpy="-3.14159265358979 -2.11841642290947E-16 2.86097492828976E-16" />
      <geometry>
        <mesh
          filename="package://gimbalrotor/meshes/thrust4.3dxml" />
      </geometry>
    </collision>
  </link>
  <joint
    name="rotor4"
    type="continuous">
    <origin
      xyz="0 0 0.0585"
      rpy="0 0 0" />
    <parent
      link="gimbal4_link" />
    <child
      link="thrust4" />
    <axis
      xyz="0 0 1" />
  </joint>
</robot>