<?xml version="1.0" encoding="UTF-8"?>
<!-- =================================================================================== -->
<!-- |    This document was autogenerated by xacro from /Users/iory/src/github.com/jsk-ros-pkg/jsk_aerial_robot/robots/gimbalrotor/urdf/grape/gimbalrotor_with_arm.urdf.xacro | -->
<!-- |    EDITING THIS FILE BY HAND IS NOT RECOMMENDED                                 | -->
<!-- =================================================================================== -->
<robot name="gimbalrotor_with_arm">
  <!-- general attribute -->
  <baselink name="fc" />
  <thrust_link name="thrust" />
  <m_f_rate value="-0.0181" />
  <!-- drug torque rate -->
  <link name="root">
    <inertial>
      <origin xyz="0 0 0" rpy="0 0 0" />
      <mass value="0.00001" />
      <inertia ixx="0.000001" ixy="0.0" ixz="0.0" iyy="0.000001" iyz="0.0" izz="0.000001" />
    </inertial>
  </link>
  <joint name="root_joint" type="fixed">
    <parent link="root" />
    <child link="main_body" />
    <origin xyz="0 0 0" rpy="0 0 0" />
    <axis xyz="0 0 1" />
  </joint>
  <link name="fc">
    <inertial>
      <origin xyz="0 0 0" rpy="0 0 0" />
      <mass value="0.00001" />
      <inertia ixx="0.000001" ixy="0.0" ixz="0.0" iyy="0.000001" iyz="0.0" izz="0.000001" />
    </inertial>
  </link>
  <joint name="fc_joint" type="fixed">
    <child link="fc" />
    <parent link="main_body" />
    <origin xyz="0 0 0" rpy="0 0 0" />
    <axis xyz="0 0 1" />
  </joint>
  <link name="main_body">
    <inertial>
      <origin xyz="-0.0041019 0.0000721 -0.0183334" rpy="0.0 -0.0 0.0" />
      <mass value="1.3193189" />
      <inertia ixx="0.0150906" ixy="-0.0000095" ixz="-0.0001112" iyy="0.0153469" iyz="-0.0000102" izz="0.0122100" />
    </inertial>
    <visual>
      <geometry>
        <mesh filename="package://gimbalrotor/urdf/grape/meshes/main_body.stl" />
      </geometry>
      <material name="__unnamed_material_1" />
      <origin xyz="0.0 0.0 0.0" rpy="0.0 -0.0 0.0" />
    </visual>
    <collision>
      <geometry>
        <!-- <mesh filename="package://gimbalrotor/urdf/grape/meshes/main_body.stl"/> -->
        <box size="0.25 0.25 0.035" />
      </geometry>
      <origin xyz="0.0 0.0 0.0" rpy="0.0 -0.0 0.0" />
    </collision>
  </link>
  <link name="gimbal1_link">
    <inertial>
      <origin xyz="0.0097185 -0.0000023 0.0115030" rpy="0.0 -0.0 0.0" />
      <mass value="0.2647482" />
      <inertia ixx="0.0004342" ixy="0.0000000" ixz="-0.0000960" iyy="0.0005399" iyz="0.0000000" izz="0.0001644" />
    </inertial>
    <visual>
      <geometry>
        <mesh filename="package://gimbalrotor/urdf/grape/meshes/gimbal1_link.stl" />
      </geometry>
      <material name="__unnamed_material_2" />
      <origin xyz="0.0 0.0 0.0" rpy="0.0 -0.0 0.0" />
    </visual>
  </link>
  <link name="thrust1">
    <inertial>
      <origin xyz="-5.83353443328605e-09 6.00431360659234e-10 0.00419839092547531" rpy="0.0 -0.0 0.0" />
      <mass value="0.011379798689915" />
      <inertia ixx="8.74001997923959e-05" ixy="-4.12766506878745e-06" ixz="-1.94275247125274e-13" iyy="6.72594264513234e-07" iyz="8.34517033335333e-15" izz="8.79093348597008e-05" />
    </inertial>
    <visual>
      <geometry>
        <mesh filename="package://gimbalrotor/urdf/grape/meshes/thrust1.stl" />
      </geometry>
      <material name="__unnamed_material_3" />
      <origin xyz="0.0 0.0 0.0" rpy="0.0 -0.0 0.0" />
    </visual>
  </link>
  <link name="gimbal2_link">
    <inertial>
      <origin xyz="0.0097185 -0.0000023 0.0115030" rpy="0.0 -0.0 0.0" />
      <mass value="0.2647482" />
      <inertia ixx="0.0004342" ixy="0.0000000" ixz="-0.0000960" iyy="0.0005399" iyz="0.0000000" izz="0.0001644" />
    </inertial>
    <visual>
      <geometry>
        <mesh filename="package://gimbalrotor/urdf/grape/meshes/gimbal2_link.stl" />
      </geometry>
      <material name="__unnamed_material_4" />
      <origin xyz="0.0 0.0 0.0" rpy="0.0 -0.0 0.0" />
    </visual>
  </link>
  <link name="thrust2">
    <inertial>
      <origin xyz="-2.56972954026935e-09 3.06808817088874e-09 0.00419843813014376" rpy="0.0 -0.0 0.0" />
      <mass value="0.0113800668107397" />
      <inertia ixx="8.73993574758916e-05" ixy="4.12756893234927e-06" ixz="-1.16071744831874e-13" iyy="6.7258088785491e-07" iyz="1.27017867936525e-13" izz="8.79084828385424e-05" />
    </inertial>
    <visual>
      <geometry>
        <mesh filename="package://gimbalrotor/urdf/grape/meshes/thrust2.stl" />
      </geometry>
      <material name="__unnamed_material_5" />
      <origin xyz="0.0 0.0 0.0" rpy="0.0 -0.0 0.0" />
    </visual>
  </link>
  <link name="gimbal3_link">
    <inertial>
      <origin xyz="0.0097185 -0.0000023 0.0115030" rpy="0.0 -0.0 0.0" />
      <mass value="0.2647482" />
      <inertia ixx="0.0004342" ixy="0.0000000" ixz="-0.0000960" iyy="0.0005399" iyz="0.0000000" izz="0.0001644" />
    </inertial>
    <visual>
      <geometry>
        <mesh filename="package://gimbalrotor/urdf/grape/meshes/gimbal3_link.stl" />
      </geometry>
      <material name="__unnamed_material_6" />
      <origin xyz="0.0 0.0 0.0" rpy="0.0 -0.0 0.0" />
    </visual>
  </link>
  <link name="thrust3">
    <inertial>
      <origin xyz="-5.83425141531535e-09 6.01800406659052e-10 0.00419839092622981" rpy="0.0 -0.0 0.0" />
      <mass value="0.0113797986875362" />
      <inertia ixx="8.74001997906142e-05" ixy="-4.12766506892759e-06" ixz="-1.9423641282498e-13" iyy="6.72594264594888e-07" iyz="8.63468898765394e-15" izz="8.79093348579925e-05" />
    </inertial>
    <visual>
      <geometry>
        <mesh filename="package://gimbalrotor/urdf/grape/meshes/thrust3.stl" />
      </geometry>
      <material name="__unnamed_material_7" />
      <origin xyz="0.0 0.0 0.0" rpy="0.0 -0.0 0.0" />
    </visual>
  </link>
  <link name="gimbal4_link">
    <inertial>
      <origin xyz="0.0097185 -0.0000023 0.0115030" rpy="0.0 -0.0 0.0" />
      <mass value="0.2647482" />
      <inertia ixx="0.0004342" ixy="0.0000000" ixz="-0.0000960" iyy="0.0005399" iyz="0.0000000" izz="0.0001644" />
    </inertial>
    <visual>
      <geometry>
        <mesh filename="package://gimbalrotor/urdf/grape/meshes/gimbal4_link.stl" />
      </geometry>
      <material name="__unnamed_material_8" />
      <origin xyz="0.0 0.0 0.0" rpy="0.0 -0.0 0.0" />
    </visual>
  </link>
  <link name="thrust4">
    <inertial>
      <origin xyz="-2.5501448175369e-09 3.18832430420899e-09 0.00419843814009516" rpy="0.0 -0.0 0.0" />
      <mass value="0.0113800667770834" />
      <inertia ixx="8.73993574510469e-05" ixy="4.12756894375054e-06" ixz="-1.15301708553968e-13" iyy="6.7258088604331e-07" iyz="1.31787422616219e-13" izz="8.79084828126607e-05" />
    </inertial>
    <visual>
      <geometry>
        <mesh filename="package://gimbalrotor/urdf/grape/meshes/thrust4.stl" />
      </geometry>
      <material name="__unnamed_material_9" />
      <origin xyz="0.0 0.0 0.0" rpy="0.0 -0.0 0.0" />
    </visual>
  </link>
  <link name="rotor_arm1">
    <inertial>
      <origin xyz="0 0 0" />
      <mass value="0.00001" />
      <inertia ixx="0.000001" ixy="0.0" ixz="0.0" iyy="0.000001" iyz="0.0" izz="0.000002" />
    </inertial>
  </link>
  <link name="rotor_arm2">
    <inertial>
      <origin xyz="0 0 0" />
      <mass value="0.00001" />
      <inertia ixx="0.000001" ixy="0.0" ixz="0.0" iyy="0.000001" iyz="0.0" izz="0.000002" />
    </inertial>
  </link>
  <link name="rotor_arm3">
    <inertial>
      <origin xyz="0 0 0" />
      <mass value="0.00001" />
      <inertia ixx="0.000001" ixy="0.0" ixz="0.0" iyy="0.000001" iyz="0.0" izz="0.000002" />
    </inertial>
  </link>
  <link name="rotor_arm4">
    <inertial>
      <origin xyz="0 0 0" />
      <mass value="0.00001" />
      <inertia ixx="0.000001" ixy="0.0" ixz="0.0" iyy="0.000001" iyz="0.0" izz="0.000002" />
    </inertial>
  </link>
  <joint name="rotor_arm1_joint" type="fixed">
    <parent link="main_body" />
    <child link="rotor_arm1" />
    <axis xyz="0 0 1" />
    <origin xyz="-0.22309 -0.22309 0.0" rpy="0.0 -0.0 -2.3562" />
  </joint>
  <joint name="rotor_arm2_joint" type="fixed">
    <parent link="main_body" />
    <child link="rotor_arm2" />
    <axis xyz="0 0 1" />
    <origin xyz="0.22309 -0.22309 0.0" rpy="-0.0 -0.0 -0.7854000000000001" />
  </joint>
  <joint name="rotor_arm3_joint" type="fixed">
    <parent link="main_body" />
    <child link="rotor_arm3" />
    <axis xyz="0 0 1" />
    <origin xyz="0.22309 0.22309 0.0" rpy="0.0 -0.0 0.7854000000000001" />
  </joint>
  <joint name="rotor_arm4_joint" type="fixed">
    <parent link="main_body" />
    <child link="rotor_arm4" />
    <axis xyz="0 0 1" />
    <origin xyz="-0.22309 0.22309 0.0" rpy="0.0 -0.0 2.3562" />
  </joint>
  <joint name="gimbal1" type="revolute">
    <limit effort="5.0" lower="-3.14" upper="3.14" velocity="10.0" />
    <parent link="main_body" />
    <child link="gimbal1_link" />
    <axis xyz="1. 0. 0." />
    <origin xyz="-0.22309 -0.22309 0.0" rpy="0.0 -0.0 -2.3562" />
  </joint>
  <joint name="rotor1" type="continuous">
    <limit effort="0.0" lower="0.0" upper="30.0" velocity="0.0" />
    <parent link="gimbal1_link" />
    <child link="thrust1" />
    <axis xyz=" 0.  0. -1." />
    <origin xyz="0.0 0.0 0.0585" rpy="0.0 -0.0 0.0" />
  </joint>
  <joint name="gimbal2" type="revolute">
    <limit effort="5.0" lower="-3.14" upper="3.14" velocity="10.0" />
    <parent link="main_body" />
    <child link="gimbal2_link" />
    <axis xyz="1. 0. 0." />
    <origin xyz="0.22309 -0.22309 0.0" rpy="-0.0 -0.0 -0.7854000000000001" />
  </joint>
  <joint name="rotor2" type="continuous">
    <limit effort="0.0" lower="0.0" upper="30.0" velocity="0.0" />
    <parent link="gimbal2_link" />
    <child link="thrust2" />
    <axis xyz="0. 0. 1." />
    <origin xyz="0.0 0.0 0.0585" rpy="0.0 -0.0 0.0" />
  </joint>
  <joint name="gimbal3" type="revolute">
    <limit effort="5.0" lower="-3.14" upper="3.14" velocity="10.0" />
    <parent link="main_body" />
    <child link="gimbal3_link" />
    <axis xyz="1. 0. 0." />
    <origin xyz="0.22309 0.22309 0.0" rpy="0.0 -0.0 0.7854000000000001" />
  </joint>
  <joint name="rotor3" type="continuous">
    <limit effort="0.0" lower="0.0" upper="30.0" velocity="0.0" />
    <parent link="gimbal3_link" />
    <child link="thrust3" />
    <axis xyz=" 0.  0. -1." />
    <origin xyz="0.0 0.0 0.0585" rpy="0.0 -0.0 0.0" />
  </joint>
  <joint name="gimbal4" type="revolute">
    <limit effort="5.0" lower="-3.14" upper="3.14" velocity="10.0" />
    <parent link="main_body" />
    <child link="gimbal4_link" />
    <axis xyz="1. 0. 0." />
    <origin xyz="-0.22309 0.22309 0.0" rpy="0.0 -0.0 2.3562" />
  </joint>
  <joint name="rotor4" type="continuous">
    <limit effort="0.0" lower="0.0" upper="30.0" velocity="0.0" />
    <parent link="gimbal4_link" />
    <child link="thrust4" />
    <axis xyz="0. 0. 1." />
    <origin xyz="0.0 0.0 0.0585" rpy="0.0 -0.0 0.0" />
  </joint>
  <transmission name="gimbal1_tran">
    <type>transmission_interface/SimpleTransmission</type>
    <joint name="gimbal1">
      <hardwareInterface>hardware_interface/EffortJointInterface</hardwareInterface>
    </joint>
    <actuator name="servo1">
      <hardwareInterface>hardware_interface/EffortJointInterface</hardwareInterface>
      <mechanicalReduction>1</mechanicalReduction>
    </actuator>
  </transmission>
  <transmission name="gimbal2_tran">
    <type>transmission_interface/SimpleTransmission</type>
    <joint name="gimbal2">
      <hardwareInterface>hardware_interface/EffortJointInterface</hardwareInterface>
    </joint>
    <actuator name="servo2">
      <hardwareInterface>hardware_interface/EffortJointInterface</hardwareInterface>
      <mechanicalReduction>1</mechanicalReduction>
    </actuator>
  </transmission>
  <transmission name="gimbal3_tran">
    <type>transmission_interface/SimpleTransmission</type>
    <joint name="gimbal3">
      <hardwareInterface>hardware_interface/EffortJointInterface</hardwareInterface>
    </joint>
    <actuator name="servo3">
      <hardwareInterface>hardware_interface/EffortJointInterface</hardwareInterface>
      <mechanicalReduction>1</mechanicalReduction>
    </actuator>
  </transmission>
  <transmission name="gimbal4_tran">
    <type>transmission_interface/SimpleTransmission</type>
    <joint name="gimbal4">
      <hardwareInterface>hardware_interface/EffortJointInterface</hardwareInterface>
    </joint>
    <actuator name="servo4">
      <hardwareInterface>hardware_interface/EffortJointInterface</hardwareInterface>
      <mechanicalReduction>1</mechanicalReduction>
    </actuator>
  </transmission>
  <transmission name="rotor_tran1">
    <type>transmission_interface/SimpleTransmission</type>
    <joint name="rotor1">
      <hardwareInterface>RotorInterface</hardwareInterface>
    </joint>
    <actuator name="rotor_actuator1">
      <hardwareInterface>RotorInterface</hardwareInterface>
      <mechanicalReduction>1</mechanicalReduction>
    </actuator>
  </transmission>
  <transmission name="rotor_tran2">
    <type>transmission_interface/SimpleTransmission</type>
    <joint name="rotor2">
      <hardwareInterface>RotorInterface</hardwareInterface>
    </joint>
    <actuator name="rotor_actuator2">
      <hardwareInterface>RotorInterface</hardwareInterface>
      <mechanicalReduction>1</mechanicalReduction>
    </actuator>
  </transmission>
  <transmission name="rotor_tran3">
    <type>transmission_interface/SimpleTransmission</type>
    <joint name="rotor3">
      <hardwareInterface>RotorInterface</hardwareInterface>
    </joint>
    <actuator name="rotor_actuator3">
      <hardwareInterface>RotorInterface</hardwareInterface>
      <mechanicalReduction>1</mechanicalReduction>
    </actuator>
  </transmission>
  <transmission name="rotor_tran4">
    <type>transmission_interface/SimpleTransmission</type>
    <joint name="rotor4">
      <hardwareInterface>RotorInterface</hardwareInterface>
    </joint>
    <actuator name="rotor_actuator4">
      <hardwareInterface>RotorInterface</hardwareInterface>
      <mechanicalReduction>1</mechanicalReduction>
    </actuator>
  </transmission>
  <material name="__unnamed_material_1">
    <color rgba="0.10980392 0.10980392 0.10980392 1.        " />
  </material>
  <material name="__unnamed_material_2">
    <color rgba="0.75294118 0.75294118 0.75294118 1.        " />
  </material>
  <material name="__unnamed_material_3">
    <color rgba="0.50196078 0.50196078 0.50196078 1.        " />
  </material>
  <material name="__unnamed_material_4">
    <color rgba="0.89803922 0.91764706 0.92941176 1.        " />
  </material>
  <material name="__unnamed_material_5">
    <color rgba="0.50196078 0.50196078 0.50196078 1.        " />
  </material>
  <material name="__unnamed_material_6">
    <color rgba="0.75294118 0.75294118 0.75294118 1.        " />
  </material>
  <material name="__unnamed_material_7">
    <color rgba="0.50196078 0.50196078 0.50196078 1.        " />
  </material>
  <material name="__unnamed_material_8">
    <color rgba="0.89803922 0.91764706 0.92941176 1.        " />
  </material>
  <material name="__unnamed_material_9">
    <color rgba="0.50196078 0.50196078 0.50196078 1.        " />
  </material>
  <!-- Include the arm macro -->
  <!-- Dummy link to attach the arm to the main body -->
  <link name="arm_dummy_link" />
  <joint name="arm_dummy_joint" type="fixed">
    <parent link="main_body" />
    <child link="arm_dummy_link" />
    <origin xyz="0.0995 0.0 -0.046" rpy="3.141592653589793 1.5707926535897934 3.141592653589793" />
  </joint>
  <!-- Joint 1: Yaw module -->
  <joint name="arm_dummy_link_to_arm_joint1_base_link_joint" type="fixed">
    <parent link="arm_dummy_link" />
    <child link="arm_joint1_base_link" />
    <origin xyz="0 0 0" rpy="0 0 -1.5707963267948966" />
  </joint>
  <link name="arm_joint1_base_link">
    <inertial>
      <origin xyz="2.05400538280698e-06 0.00964614213009143 0.0328157127384981" rpy="0.0 -0.0 0.0" />
      <mass value="0.0974969477576165" />
      <inertia ixx="2.94983710615554e-05" ixy="8.65358355557671e-09" ixz="-5.99019648532088e-09" iyy="3.11696241448887e-05" iyz="1.32416975855121e-06" izz="2.3568380981746e-05" />
    </inertial>
    <visual>
      <geometry>
        <mesh filename="package://gimbalrotor/urdf/grape/meshes/arm/screw_yaw_module_dynamixel_side/base_link.dae" />
      </geometry>
      <material name="arm_joint1___unnamed_material_1" />
      <origin xyz="0.0 0.0 0.0" rpy="1.5707963267949003 2.83742224257185e-17 5.37764277552873e-17" />
    </visual>
    <collision>
      <geometry>
        <mesh filename="package://gimbalrotor/urdf/grape/meshes/arm/screw_yaw_module_dynamixel_side/base_link.stl" />
      </geometry>
      <origin xyz="0.0 0.0 0.0" rpy="1.5707963267949003 2.83742224257185e-17 5.37764277552873e-17" />
    </collision>
  </link>
  <link name="arm_joint1_link1">
    <inertial>
      <origin xyz="0.0315627099580794 3.23428430836527e-05 0.000305100560390667" rpy="0.0 -0.0 0.0" />
      <mass value="0.0155927868590324" />
      <inertia ixx="4.31040540970899e-06" ixy="-1.84501397306783e-10" ixz="1.71628424283485e-09" iyy="2.33860081225919e-06" iyz="5.31064452921531e-10" izz="2.37493267246664e-06" />
    </inertial>
    <visual>
      <geometry>
        <mesh filename="package://gimbalrotor/urdf/grape/meshes/arm/screw_yaw_module_dynamixel_side/link1.dae" />
      </geometry>
      <material name="arm_joint1___unnamed_material_2" />
      <origin xyz="-0.00399999999999988 1.52187655629222e-16 -0.0285" rpy="1.5707963267949003 6.48786257890944e-17 -1.5707963267949003" />
    </visual>
    <collision>
      <geometry>
        <mesh filename="package://gimbalrotor/urdf/grape/meshes/arm/screw_yaw_module_dynamixel_side/link1.stl" />
      </geometry>
      <origin xyz="-0.00399999999999988 1.52187655629222e-16 -0.0285" rpy="1.5707963267949003 6.48786257890944e-17 -1.5707963267949003" />
    </collision>
  </link>
  <link name="arm_joint1_dummy_link" />
  <joint name="arm_joint1_joint1" type="revolute">
    <limit effort="0.0" lower="-3.14" upper="3.14" velocity="0.0" />
    <parent link="arm_joint1_base_link" />
    <child link="arm_joint1_link1" />
    <axis xyz="-1.  0.  0." />
    <origin xyz="0.0 0.004 0.0285" rpy="0.0 -0.0 1.5708" />
  </joint>
  <joint name="arm_joint1_dummy_joint" type="fixed">
    <limit effort="0.0" velocity="0.0" />
    <parent link="arm_joint1_link1" />
    <child link="arm_joint1_dummy_link" />
    <axis xyz="0. 0. 0." />
    <origin xyz="0.0365 0.0 0.0" rpy="-3.141592653589793 -1.5707926535897934 3.141592653589793" />
  </joint>
  <material name="arm_joint1___unnamed_material_1">
    <color rgba="1. 1. 1. 1." />
  </material>
  <material name="arm_joint1___unnamed_material_2">
    <color rgba="0.29803922 0.29803922 0.29803922 1.        " />
  </material>
  <!-- 90deg elbow module -->
  <joint name="arm_90deg_arm_joint1_dummy_link_to_arm_90deg_base_link_joint" type="fixed">
    <parent link="arm_joint1_dummy_link" />
    <child link="arm_90deg_base_link" />
    <origin xyz="0 0 0" rpy="0 3.14 -3.14159" />
  </joint>
  <link name="arm_90deg_base_link">
    <inertial>
      <origin xyz="0.0103968242657149 9.09918637167594e-06 0.0216864027648383" rpy="0.0 -0.0 0.0" />
      <mass value="0.0326146601839408" />
      <inertia ixx="7.31440757794881e-06" ixy="1.87744826133299e-09" ixz="-3.64840488298395e-07" iyy="5.22875275247874e-06" iyz="1.92378635215547e-09" izz="6.19875400864727e-06" />
    </inertial>
    <visual>
      <geometry>
        <mesh filename="package://gimbalrotor/urdf/grape/meshes/arm/screw_90deg_module/base_link.dae" />
      </geometry>
      <material name="arm_90deg___unnamed_material_1" />
      <origin xyz="0.0285 -1.88586037787625e-16 0.0285000000000001" rpy="3.14159265358979 -2.52653528463934e-16 1.57079632679489" />
    </visual>
    <collision>
      <geometry>
        <mesh filename="package://gimbalrotor/urdf/grape/meshes/arm/screw_90deg_module/base_link.dae" />
      </geometry>
      <origin xyz="0.0285 -1.88586037787625e-16 0.0285000000000001" rpy="3.14159265358979 -2.52653528463934e-16 1.57079632679489" />
    </collision>
  </link>
  <link name="arm_90deg_dummy_link" />
  <joint name="arm_90deg_dummy_joint" type="fixed">
    <limit effort="0.0" velocity="0.0" />
    <parent link="arm_90deg_base_link" />
    <child link="arm_90deg_dummy_link" />
    <axis xyz="0. 0. 0." />
    <origin xyz="0.0285 0.0 0.0285000000000001" rpy="3.141592653589793 1.570796326794893 3.141592653589793" />
  </joint>
  <material name="arm_90deg___unnamed_material_1">
    <color rgba="0.29803922 0.29803922 0.29803922 1.        " />
  </material>
  <!-- 200mm pipe module -->
  <joint name="arm_90deg_dummy_link_to_arm_pipe_base_link_joint" type="fixed">
    <parent link="arm_90deg_dummy_link" />
    <child link="arm_pipe_base_link" />
    <origin xyz="0 0 0" rpy="0 0 0" />
  </joint>
  <link name="arm_pipe_base_link">
    <inertial>
      <origin xyz="0.0314472120441254 0.0185600648406693 0.999996863971173" rpy="0.0 -0.0 0.0" />
      <mass value="0.0784" />
      <inertia ixx="1.92067336342704e-05" ixy="4.86844738251007e-08" ixz="-3.58103918098541e-08" iyy="0.000556258110321859" iyz="-3.52324723813976e-10" izz="0.000556910936857427" />
    </inertial>
    <visual>
      <geometry>
        <mesh filename="package://gimbalrotor/urdf/grape/meshes/arm/screw_200mmpipe_module/base_link.dae" />
      </geometry>
      <material name="arm_pipe___unnamed_material_1" />
      <origin xyz="-0.018612068965513 1.00000000000001 0.146669004611067" rpy="-1.5707963267948835 1.570796326794893 3.141592653589793" />
    </visual>
    <collision>
      <geometry>
        <mesh filename="package://gimbalrotor/urdf/grape/meshes/arm/screw_200mmpipe_module/base_link.stl" />
      </geometry>
      <origin xyz="-0.018612068965513 1.00000000000001 0.146669004611067" rpy="-1.5707963267948835 1.570796326794893 3.141592653589793" />
    </collision>
  </link>
  <link name="arm_pipe_dummy_link" />
  <joint name="arm_pipe_dummy_joint" type="fixed">
    <limit effort="0.0" velocity="0.0" />
    <parent link="arm_pipe_base_link" />
    <child link="arm_pipe_dummy_link" />
    <axis xyz="0. 0. 0." />
    <origin xyz="0.0 0.0 0.221" rpy="0.0 -0.0 0.0" />
  </joint>
  <material name="arm_pipe___unnamed_material_1">
    <color rgba="0.75294118 0.75294118 0.75294118 1.        " />
  </material>
  <!-- Joint 2: Hinge module -->
  <joint name="arm_pipe_dummy_link_to_arm_joint2_base_link_joint" type="fixed">
    <parent link="arm_pipe_dummy_link" />
    <child link="arm_joint2_base_link" />
    <origin xyz="0 0 0" rpy="0 0 0" />
  </joint>
  <link name="arm_joint2_base_link">
    <inertial>
      <origin xyz="-0.000125522807867996 6.25397854935558e-05 0.0152522387170004" rpy="0.0 -0.0 0.0" />
      <mass value="0.0138575446641172" />
      <inertia ixx="3.55557358743012e-06" ixy="6.50933428796727e-10" ixz="4.46136622179202e-08" iyy="6.32031958633877e-06" iyz="-1.9253050825893e-08" izz="4.57885870672051e-06" />
    </inertial>
    <visual>
      <geometry>
        <mesh filename="package://gimbalrotor/urdf/grape/meshes/arm/screw_hinge_module_dynamixel/base_link.dae" />
      </geometry>
      <material name="arm_joint2___unnamed_material_1" />
      <origin xyz="0.0 0.0 0.0" rpy="1.5707963267949003 -2.99239799605999e-16 -1.5707963267949003" />
    </visual>
    <collision>
      <geometry>
        <mesh filename="package://gimbalrotor/urdf/grape/meshes/arm/screw_hinge_module_dynamixel/base_link.stl" />
      </geometry>
      <origin xyz="0.0 0.0 0.0" rpy="1.5707963267949003 -2.99239799605999e-16 -1.5707963267949003" />
    </collision>
  </link>
  <link name="arm_joint2_link1">
    <inertial>
      <origin xyz="0.000338644241900288 0.0191313185456315 5.78940488087729e-07" rpy="0.0 -0.0 0.0" />
      <mass value="0.0612328998065947" />
      <inertia ixx="1.33040989290318e-05" ixy="2.5040849060523e-07" ixz="4.80025662292933e-09" iyy="1.27387024978889e-05" iyz="-4.2924245435293e-09" izz="1.50538962870715e-05" />
    </inertial>
    <visual>
      <geometry>
        <mesh filename="package://gimbalrotor/urdf/grape/meshes/arm/screw_hinge_module_dynamixel/link1.dae" />
      </geometry>
      <material name="arm_joint2___unnamed_material_2" />
      <origin xyz="2.09657352239695e-18 -0.035 1.00064680020069e-17" rpy="3.141592653589793 1.570796326794893 3.141592653589793" />
    </visual>
    <collision>
      <geometry>
        <mesh filename="package://gimbalrotor/urdf/grape/meshes/arm/screw_hinge_module_dynamixel/link1.stl" />
      </geometry>
      <origin xyz="2.09657352239695e-18 -0.035 1.00064680020069e-17" rpy="3.141592653589793 1.570796326794893 3.141592653589793" />
    </collision>
  </link>
  <link name="arm_joint2_dummy_link" />
  <joint name="arm_joint2_joint1" type="revolute">
    <limit effort="0.0" lower="-0.567" upper="0.567" velocity="0.0" />
    <parent link="arm_joint2_base_link" />
    <child link="arm_joint2_link1" />
    <axis xyz="-1.  0.  0." />
    <origin xyz="0.0 0.0 0.035" rpy="1.5708 -0.0 3.1415853071795867" />
  </joint>
  <joint name="arm_joint2_dummy_joint" type="fixed">
    <limit effort="0.0" velocity="0.0" />
    <parent link="arm_joint2_link1" />
    <child link="arm_joint2_dummy_link" />
    <axis xyz="0. 0. 0." />
    <origin xyz="0.0 0.045 0.0" rpy="-1.5707926535897931 -1.5707926535897934 3.141592653589793" />
  </joint>
  <material name="arm_joint2___unnamed_material_1">
    <color rgba="0.29803922 0.29803922 0.29803922 1.        " />
  </material>
  <material name="arm_joint2___unnamed_material_2">
    <color rgba="0.75294118 0.75294118 0.75294118 1.        " />
  </material>
  <!-- Joint 3: Hinge module -->
  <joint name="arm_joint2_dummy_link_to_arm_joint3_base_link_joint" type="fixed">
    <parent link="arm_joint2_dummy_link" />
    <child link="arm_joint3_base_link" />
    <origin xyz="0 0 0" rpy="0 3.14 -1.5707963267948966" />
  </joint>
  <link name="arm_joint3_base_link">
    <inertial>
      <origin xyz="-0.000125522807867996 6.25397854935558e-05 0.0152522387170004" rpy="0.0 -0.0 0.0" />
      <mass value="0.0138575446641172" />
      <inertia ixx="3.55557358743012e-06" ixy="6.50933428796727e-10" ixz="4.46136622179202e-08" iyy="6.32031958633877e-06" iyz="-1.9253050825893e-08" izz="4.57885870672051e-06" />
    </inertial>
    <visual>
      <geometry>
        <mesh filename="package://gimbalrotor/urdf/grape/meshes/arm/screw_hinge_module_dynamixel/base_link.dae" />
      </geometry>
      <material name="arm_joint3___unnamed_material_1" />
      <origin xyz="0.0 0.0 0.0" rpy="1.5707963267949003 -2.99239799605999e-16 -1.5707963267949003" />
    </visual>
    <collision>
      <geometry>
        <mesh filename="package://gimbalrotor/urdf/grape/meshes/arm/screw_hinge_module_dynamixel/base_link.stl" />
      </geometry>
      <origin xyz="0.0 0.0 0.0" rpy="1.5707963267949003 -2.99239799605999e-16 -1.5707963267949003" />
    </collision>
  </link>
  <link name="arm_joint3_link1">
    <inertial>
      <origin xyz="0.000338644241900288 0.0191313185456315 5.78940488087729e-07" rpy="0.0 -0.0 0.0" />
      <mass value="0.0612328998065947" />
      <inertia ixx="1.33040989290318e-05" ixy="2.5040849060523e-07" ixz="4.80025662292933e-09" iyy="1.27387024978889e-05" iyz="-4.2924245435293e-09" izz="1.50538962870715e-05" />
    </inertial>
    <visual>
      <geometry>
        <mesh filename="package://gimbalrotor/urdf/grape/meshes/arm/screw_hinge_module_dynamixel/link1.dae" />
      </geometry>
      <material name="arm_joint3___unnamed_material_2" />
      <origin xyz="2.09657352239695e-18 -0.035 1.00064680020069e-17" rpy="3.141592653589793 1.570796326794893 3.141592653589793" />
    </visual>
    <collision>
      <geometry>
        <mesh filename="package://gimbalrotor/urdf/grape/meshes/arm/screw_hinge_module_dynamixel/link1.stl" />
      </geometry>
      <origin xyz="2.09657352239695e-18 -0.035 1.00064680020069e-17" rpy="3.141592653589793 1.570796326794893 3.141592653589793" />
    </collision>
  </link>
  <link name="arm_joint3_dummy_link" />
  <joint name="arm_joint3_joint1" type="revolute">
    <limit effort="0.0" lower="-0.567" upper="0.567" velocity="0.0" />
    <parent link="arm_joint3_base_link" />
    <child link="arm_joint3_link1" />
    <axis xyz="-1.  0.  0." />
    <origin xyz="0.0 0.0 0.035" rpy="1.5708 -0.0 3.1415853071795867" />
  </joint>
  <joint name="arm_joint3_dummy_joint" type="fixed">
    <limit effort="0.0" velocity="0.0" />
    <parent link="arm_joint3_link1" />
    <child link="arm_joint3_dummy_link" />
    <axis xyz="0. 0. 0." />
    <origin xyz="0.0 0.045 0.0" rpy="-1.5707926535897931 -1.5707926535897934 3.141592653589793" />
  </joint>
  <material name="arm_joint3___unnamed_material_1">
    <color rgba="0.29803922 0.29803922 0.29803922 1.        " />
  </material>
  <material name="arm_joint3___unnamed_material_2">
    <color rgba="0.75294118 0.75294118 0.75294118 1.        " />
  </material>
  <!-- Joint 4: Hinge module -->
  <joint name="arm_joint3_dummy_link_to_arm_joint4_base_link_joint" type="fixed">
    <parent link="arm_joint3_dummy_link" />
    <child link="arm_joint4_base_link" />
    <origin xyz="0 0 0" rpy="0 3.14 0" />
  </joint>
  <link name="arm_joint4_base_link">
    <inertial>
      <origin xyz="-0.000125522807867996 6.25397854935558e-05 0.0152522387170004" rpy="0.0 -0.0 0.0" />
      <mass value="0.0138575446641172" />
      <inertia ixx="3.55557358743012e-06" ixy="6.50933428796727e-10" ixz="4.46136622179202e-08" iyy="6.32031958633877e-06" iyz="-1.9253050825893e-08" izz="4.57885870672051e-06" />
    </inertial>
    <visual>
      <geometry>
        <mesh filename="package://gimbalrotor/urdf/grape/meshes/arm/screw_hinge_module_dynamixel/base_link.dae" />
      </geometry>
      <material name="arm_joint4___unnamed_material_1" />
      <origin xyz="0.0 0.0 0.0" rpy="1.5707963267949003 -2.99239799605999e-16 -1.5707963267949003" />
    </visual>
    <collision>
      <geometry>
        <mesh filename="package://gimbalrotor/urdf/grape/meshes/arm/screw_hinge_module_dynamixel/base_link.stl" />
      </geometry>
      <origin xyz="0.0 0.0 0.0" rpy="1.5707963267949003 -2.99239799605999e-16 -1.5707963267949003" />
    </collision>
  </link>
  <link name="arm_joint4_link1">
    <inertial>
      <origin xyz="0.000338644241900288 0.0191313185456315 5.78940488087729e-07" rpy="0.0 -0.0 0.0" />
      <mass value="0.0612328998065947" />
      <inertia ixx="1.33040989290318e-05" ixy="2.5040849060523e-07" ixz="4.80025662292933e-09" iyy="1.27387024978889e-05" iyz="-4.2924245435293e-09" izz="1.50538962870715e-05" />
    </inertial>
    <visual>
      <geometry>
        <mesh filename="package://gimbalrotor/urdf/grape/meshes/arm/screw_hinge_module_dynamixel/link1.dae" />
      </geometry>
      <material name="arm_joint4___unnamed_material_2" />
      <origin xyz="2.09657352239695e-18 -0.035 1.00064680020069e-17" rpy="3.141592653589793 1.570796326794893 3.141592653589793" />
    </visual>
    <collision>
      <geometry>
        <mesh filename="package://gimbalrotor/urdf/grape/meshes/arm/screw_hinge_module_dynamixel/link1.stl" />
      </geometry>
      <origin xyz="2.09657352239695e-18 -0.035 1.00064680020069e-17" rpy="3.141592653589793 1.570796326794893 3.141592653589793" />
    </collision>
  </link>
  <link name="arm_joint4_dummy_link" />
  <joint name="arm_joint4_joint1" type="revolute">
    <limit effort="0.0" lower="-0.567" upper="0.567" velocity="0.0" />
    <parent link="arm_joint4_base_link" />
    <child link="arm_joint4_link1" />
    <axis xyz="-1.  0.  0." />
    <origin xyz="0.0 0.0 0.035" rpy="1.5708 -0.0 3.1415853071795867" />
  </joint>
  <joint name="arm_joint4_dummy_joint" type="fixed">
    <limit effort="0.0" velocity="0.0" />
    <parent link="arm_joint4_link1" />
    <child link="arm_joint4_dummy_link" />
    <axis xyz="0. 0. 0." />
    <origin xyz="0.0 0.045 0.0" rpy="-1.5707926535897931 -1.5707926535897934 3.141592653589793" />
  </joint>
  <material name="arm_joint4___unnamed_material_1">
    <color rgba="0.29803922 0.29803922 0.29803922 1.        " />
  </material>
  <material name="arm_joint4___unnamed_material_2">
    <color rgba="0.75294118 0.75294118 0.75294118 1.        " />
  </material>
  <!-- Joint 5: Drive module -->
  <joint name="arm_joint4_dummy_link_to_arm_joint5_base_link_joint" type="fixed">
    <parent link="arm_joint4_dummy_link" />
    <child link="arm_joint5_base_link" />
    <origin xyz="0 0 0" rpy="0 3.14 3.14" />
  </joint>
  <link name="arm_joint5_base_link">
    <inertial>
      <origin xyz="-0.00765228787056842 -4.62071402854722e-06 0.030577013511963" rpy="0.0 -0.0 0.0" />
      <mass value="0.0789612388386658" />
      <inertia ixx="1.79587389811886e-05" ixy="-4.55577944240825e-09" ixz="-4.90809821784595e-07" iyy="2.50354890172928e-05" iyz="-4.43481793491922e-09" izz="2.37470837281577e-05" />
    </inertial>
    <visual>
      <geometry>
        <mesh filename="package://gimbalrotor/urdf/grape/meshes/arm/screw_drive_module_dynamixel/base_link.dae" />
      </geometry>
      <material name="arm_joint5___unnamed_material_1" />
      <origin xyz="-1.51387102717471e-18 5.99174275367398e-19 0.0457" rpy="1.5707963267949003 -0.0 1.5707963267949003" />
    </visual>
    <collision>
      <geometry>
        <mesh filename="package://gimbalrotor/urdf/grape/meshes/arm/screw_drive_module_dynamixel/base_link.stl" />
      </geometry>
      <origin xyz="-1.51387102717471e-18 5.99174275367398e-19 0.0457" rpy="1.5707963267949003 -0.0 1.5707963267949003" />
    </collision>
  </link>
  <link name="arm_joint5_link1">
    <inertial>
      <origin xyz="-0.000256062171402636 -1.23464794906739e-10 0.0223133729686151" rpy="0.0 -0.0 0.0" />
      <mass value="0.00140627867032843" />
      <inertia ixx="3.69305972647323e-08" ixy="4.70059675645385e-16" ixz="1.36569540430659e-09" iyy="4.37001527382599e-08" iyz="4.21205301040001e-16" izz="6.37416918942377e-08" />
    </inertial>
    <visual>
      <geometry>
        <mesh filename="package://gimbalrotor/urdf/grape/meshes/arm/screw_drive_module_dynamixel/link1.dae" />
      </geometry>
      <material name="arm_joint5___unnamed_material_2" />
      <origin xyz="-2.15167357330528e-17 -1.20100411619191e-17 0.0152" rpy="1.5707963267949003 -1.09476442525376e-47 1.5707963267949003" />
    </visual>
    <collision>
      <geometry>
        <mesh filename="package://gimbalrotor/urdf/grape/meshes/arm/screw_drive_module_dynamixel/link1.stl" />
      </geometry>
      <origin xyz="-2.15167357330528e-17 -1.20100411619191e-17 0.0152" rpy="1.5707963267949003 -1.09476442525376e-47 1.5707963267949003" />
    </collision>
  </link>
  <link name="arm_joint5_dummy_link" />
  <joint name="arm_joint5_joint1" type="continuous">
    <limit effort="0.0" velocity="0.0" />
    <parent link="arm_joint5_base_link" />
    <child link="arm_joint5_link1" />
    <axis xyz=" 0.  0. -1." />
    <origin xyz="0.0 0.0 0.0305" rpy="0.0 -0.0 0.0" />
  </joint>
  <joint name="arm_joint5_dummy_joint" type="fixed">
    <limit effort="0.0" velocity="0.0" />
    <parent link="arm_joint5_base_link" />
    <child link="arm_joint5_dummy_link" />
    <axis xyz="0. 0. 0." />
    <origin xyz="0.0 0.0 0.058" rpy="0.0 -0.0 -3.1415853071795867" />
  </joint>
  <material name="arm_joint5___unnamed_material_1">
    <color rgba="0.75294118 0.75294118 0.75294118 1.        " />
  </material>
  <material name="arm_joint5___unnamed_material_2">
    <color rgba="0.29803922 0.29803922 0.29803922 1.        " />
  </material>
  <!-- Gripper -->
  <joint name="arm_joint5_dummy_link_to_arm_gripper_base_link_joint" type="fixed">
    <parent link="arm_joint5_dummy_link" />
    <child link="arm_gripper_base_link" />
    <origin xyz="0 0 0" rpy="0 0 0" />
  </joint>
  <link name="arm_gripper_base_link">
    <inertial>
      <origin xyz="-8.31656604743406e-05 6.17407712109358e-07 0.0172789824004518" rpy="0.0 -0.0 0.0" />
      <mass value="0.0367410396327177" />
      <inertia ixx="2.74000444301134e-05" ixy="2.05651795964491e-09" ixz="1.05170944657198e-08" iyy="3.92773312962098e-06" iyz="1.41490289935768e-10" izz="2.96000106477188e-05" />
    </inertial>
    <visual>
      <geometry>
        <mesh filename="package://gimbalrotor/urdf/grape/meshes/arm/vial_pick_module/base_link.dae" />
      </geometry>
      <material name="arm_gripper___unnamed_material_1" />
      <origin xyz="0.0 0.0 0.0" rpy="-1.1895621213035508e-32 -2.44929359829471e-16 1.57079632679489" />
    </visual>
    <collision>
      <geometry>
        <mesh filename="package://gimbalrotor/urdf/grape/meshes/arm/vial_pick_module/base_link.stl" />
      </geometry>
      <origin xyz="0.0 0.0 0.0" rpy="-1.1895621213035508e-32 -2.44929359829471e-16 1.57079632679489" />
    </collision>
  </link>
  <link name="arm_gripper_pick_dummy_link">
    <inertial>
      <origin xyz="-0.000120038522656072 -5.20570211972105e-12 -0.0147957403917136" rpy="0.0 -0.0 0.0" />
      <mass value="0.00343282009982582" />
      <inertia ixx="1.16286941033441e-07" ixy="8.67661870278422e-18" ixz="-1.77466824391762e-09" iyy="1.07255119256354e-07" iyz="-3.37024679420742e-17" izz="1.22297072354454e-07" />
    </inertial>
    <visual>
      <geometry>
        <mesh filename="package://gimbalrotor/urdf/grape/meshes/arm/vial_pick_module/pick_dummy_link.dae" />
      </geometry>
      <material name="arm_gripper___unnamed_material_2" />
      <origin xyz="-1.43008831174061e-17 -1.78863404261684e-17 -0.023" rpy="-1.3497194182685498e-15 -7.618871916663648e-16 -1.5707963267944498" />
    </visual>
    <collision>
      <geometry>
        <mesh filename="package://gimbalrotor/urdf/grape/meshes/arm/vial_pick_module/pick_dummy_link.stl" />
      </geometry>
      <origin xyz="-1.43008831174061e-17 -1.78863404261684e-17 -0.023" rpy="-1.3497194182685498e-15 -7.618871916663648e-16 -1.5707963267944498" />
    </collision>
  </link>
  <link name="arm_gripper_gripper_link1">
    <inertial>
      <origin xyz="-0.00786415967836717 -0.0219871091816924 0.0229800428255594" rpy="0.0 -0.0 0.0" />
      <mass value="0.0266986294658226" />
      <inertia ixx="3.98880329468621e-06" ixy="1.86640977240353e-07" ixz="-1.1651136084322e-07" iyy="4.301768396309e-06" iyz="2.46993792736072e-07" izz="3.1771479602296e-06" />
    </inertial>
    <visual>
      <geometry>
        <mesh filename="package://gimbalrotor/urdf/grape/meshes/arm/vial_pick_module/gripper_link1.dae" />
      </geometry>
      <material name="arm_gripper___unnamed_material_3" />
      <origin xyz="-0.00699999999999998 1.0683109299301e-18 -0.0235" rpy="6.301392866405062e-16 -9.87992243989157e-16 -1.5707963267949006" />
    </visual>
    <collision>
      <geometry>
        <mesh filename="package://gimbalrotor/urdf/grape/meshes/arm/vial_pick_module/gripper_link1.stl" />
      </geometry>
      <origin xyz="-0.00699999999999998 1.0683109299301e-18 -0.0235" rpy="6.301392866405062e-16 -9.87992243989157e-16 -1.5707963267949006" />
    </collision>
  </link>
  <link name="arm_gripper_gripper_link2">
    <inertial>
      <origin xyz="0.00786416008938544 0.0219871091816897 0.0236476776647334" rpy="0.0 -0.0 0.0" />
      <mass value="0.0266986294658226" />
      <inertia ixx="3.9888032946862e-06" ixy="1.86636813590827e-07" ixz="1.16511360843049e-07" iyy="4.301768396309e-06" iyz="-9.59549183617184e-08" izz="3.1771479602296e-06" />
    </inertial>
    <visual>
      <geometry>
        <mesh filename="package://gimbalrotor/urdf/grape/meshes/arm/vial_pick_module/gripper_link2.dae" />
      </geometry>
      <material name="arm_gripper___unnamed_material_4" />
      <origin xyz="0.00700000000000003 1.31857538436738e-16 -0.0235" rpy="5.703715567474983e-16 -1.04683580036436e-15 -1.5707963267949006" />
    </visual>
    <collision>
      <geometry>
        <mesh filename="package://gimbalrotor/urdf/grape/meshes/arm/vial_pick_module/gripper_link2.stl" />
      </geometry>
      <origin xyz="0.00700000000000003 1.31857538436738e-16 -0.0235" rpy="5.703715567474983e-16 -1.04683580036436e-15 -1.5707963267949006" />
    </collision>
  </link>
  <joint name="arm_gripper_pick_dummy_joint" type="revolute">
    <limit effort="0.0" lower="-2.36" upper="2.36" velocity="0.0" />
    <parent link="arm_gripper_base_link" />
    <child link="arm_gripper_pick_dummy_link" />
    <axis xyz="0. 0. 1." />
    <origin xyz="0.0 0.0 0.023" rpy="0.0 -0.0 3.14159265358933" />
  </joint>
  <joint name="arm_gripper_gripper_joint1" type="prismatic">
    <limit effort="0.0" lower="-0.013" upper="0.018" velocity="0.0" />
    <mimic joint="arm_gripper_pick_dummy_joint" multiplier="-0.007" offset="0.0" />
    <parent link="arm_gripper_base_link" />
    <child link="arm_gripper_gripper_link1" />
    <axis xyz="0. 1. 0." />
    <origin xyz="-0.007 0.0 0.0235" rpy="0.0 -0.0 -3.1415853071795867" />
  </joint>
  <joint name="arm_gripper_gripper_joint2" type="prismatic">
    <limit effort="0.0" lower="-0.013" upper="0.018" velocity="0.0" />
    <mimic joint="arm_gripper_pick_dummy_joint" multiplier="-0.007" offset="0.0" />
    <parent link="arm_gripper_base_link" />
    <child link="arm_gripper_gripper_link2" />
    <axis xyz=" 0. -1.  0." />
    <origin xyz="0.007 0.0 0.0235" rpy="0.0 -0.0 -3.1415853071795867" />
  </joint>
  <material name="arm_gripper___unnamed_material_1">
    <color rgba="0.75294118 0.75294118 0.75294118 1.        " />
  </material>
  <material name="arm_gripper___unnamed_material_2">
    <color rgba="0.29803922 0.29803922 0.29803922 1.        " />
  </material>
  <material name="arm_gripper___unnamed_material_3">
    <color rgba="1. 1. 1. 1." />
  </material>
  <material name="arm_gripper___unnamed_material_4">
    <color rgba="1. 1. 1. 1." />
  </material>
</robot>
