<?xml version='1.0' encoding='UTF-8'?>
<robot name="gimbalrotor" xmlns:xacro="http://www.ros.org/wiki/xacro">

  <link name="main_body">
    <inertial>
      <!-- <origin xyz="-0.00202460418348044 -0.000510481706680737 -0.0123651551887967" rpy="0.0 -0.0 0.0"/> -->
      <!-- <mass value="1.40071559053294"/> -->
      <!-- <inertia ixx="0.00167259281385339" ixy="-1.88191851673578e-07" ixz="7.17787328777675e-07" iyy="0.00167984573863287" iyz="4.03619596691479e-08" izz="0.00304193991451692"/> -->
    </inertial>
    <visual>
      <geometry>
        <mesh filename="package://gimbalrotor/grape/meshes/main_body.dae"/>
      </geometry>
      <material name="__unnamed_material_1"/>
      <origin xyz="0.0 0.0 0.0" rpy="0.0 -0.0 0.0"/>
    </visual>
    <collision>
      <geometry>
        <mesh filename="package://gimbalrotor/grape/meshes/main_body.stl"/>
      </geometry>
      <origin xyz="0.0 0.0 0.0" rpy="0.0 -0.0 0.0"/>
    </collision>
  </link>

  <link name="gimbal1_link">
    <inertial>
      <origin xyz="-0.00926567494919711 1.9703972765894e-06 0.0128616849753725" rpy="0.0 -0.0 0.0"/>
      <mass value="0.243868409767181"/>
      <inertia ixx="4.70366622152039e-05" ixy="-5.23334464430229e-09" ixz="-4.58510270196035e-07" iyy="4.49457729860046e-05" iyz="-2.62506744960952e-09" izz="4.59133399019853e-05"/>
      <!-- <origin xyz="-0.00926567494919711 1.9703972765894e-06 0.0128616849753725" rpy="0.0 -0.0 0.0"/> -->
      <!-- <mass value="0.243868409767181"/> -->
      <!-- <inertia ixx="4.70366622152039e-05" ixy="-5.23334464430229e-09" ixz="-4.58510270196035e-07" iyy="4.49457729860046e-05" iyz="-2.62506744960952e-09" izz="4.59133399019853e-05"/> -->
    </inertial>
    <visual>
      <geometry>
        <mesh filename="package://gimbalrotor/grape/meshes/gimbal1_link.dae"/>
      </geometry>
      <material name="__unnamed_material_2"/>
      <origin xyz="0.0 0.0 0.0" rpy="0.0 -0.0 0.0"/>
    </visual>
    <collision>
      <geometry>
        <mesh filename="package://gimbalrotor/grape/meshes/gimbal1_link.stl"/>
      </geometry>
      <origin xyz="0.0 0.0 0.0" rpy="0.0 -0.0 0.0"/>
    </collision>
  </link>

  <link name="thrust1">
    <inertial>
      <origin xyz="-5.83353443328605e-09 6.00431360659234e-10 0.00419839092547531" rpy="0.0 -0.0 0.0"/>
      <mass value="0.011379798689915"/>
      <inertia ixx="8.74001997923959e-05" ixy="-4.12766506878745e-06" ixz="-1.94275247125274e-13" iyy="6.72594264513234e-07" iyz="8.34517033335333e-15" izz="8.79093348597008e-05"/>
    </inertial>
    <visual>
      <geometry>
        <mesh filename="package://gimbalrotor/grape/meshes/thrust1.dae"/>
      </geometry>
      <material name="__unnamed_material_3"/>
      <origin xyz="0.0 0.0 0.0" rpy="0.0 -0.0 0.0"/>
    </visual>
    <collision>
      <geometry>
        <mesh filename="package://gimbalrotor/grape/meshes/thrust1.stl"/>
      </geometry>
      <origin xyz="0.0 0.0 0.0" rpy="0.0 -0.0 0.0"/>
    </collision>
  </link>

  <link name="gimbal2_link">
    <inertial>
      <origin xyz="-0.00926567494919772 1.97039712329184e-06 0.0128616849753724" rpy="0.0 -0.0 0.0"/>
      <mass value="0.243868409767181"/>
      <inertia ixx="4.70366622152039e-05" ixy="-5.23334464430183e-09" ixz="-4.5851027019603e-07" iyy="4.49457729860046e-05" iyz="-2.62506744960961e-09" izz="4.59133399019854e-05"/>
      <!-- <origin xyz="-0.00926567494919767 1.97039727626247e-06 0.0128616849753725" rpy="0.0 -0.0 0.0"/> -->
      <!-- <mass value="0.243868409767181"/> -->
      <!-- <inertia ixx="4.70366622152039e-05" ixy="-5.23334464430243e-09" ixz="-4.58510270196032e-07" iyy="4.49457729860046e-05" iyz="-2.62506744960964e-09" izz="4.59133399019854e-05"/> -->
    </inertial>
    <visual>
      <geometry>
        <mesh filename="package://gimbalrotor/grape/meshes/gimbal2_link.dae"/>
      </geometry>
      <material name="__unnamed_material_4"/>
      <origin xyz="0.0 0.0 0.0" rpy="0.0 -0.0 0.0"/>
    </visual>
    <collision>
      <geometry>
        <mesh filename="package://gimbalrotor/grape/meshes/gimbal2_link.stl"/>
      </geometry>
      <origin xyz="0.0 0.0 0.0" rpy="0.0 -0.0 0.0"/>
    </collision>
  </link>

  <link name="thrust2">
    <inertial>
      <origin xyz="-2.56972954026935e-09 3.06808817088874e-09 0.00419843813014376" rpy="0.0 -0.0 0.0"/>
      <mass value="0.0113800668107397"/>
      <inertia ixx="8.73993574758916e-05" ixy="4.12756893234927e-06" ixz="-1.16071744831874e-13" iyy="6.7258088785491e-07" iyz="1.27017867936525e-13" izz="8.79084828385424e-05"/>
    </inertial>
    <visual>
      <geometry>
        <mesh filename="package://gimbalrotor/grape/meshes/thrust2.dae"/>
      </geometry>
      <material name="__unnamed_material_5"/>
      <origin xyz="0.0 0.0 0.0" rpy="0.0 -0.0 0.0"/>
    </visual>
    <collision>
      <geometry>
        <mesh filename="package://gimbalrotor/grape/meshes/thrust2.stl"/>
      </geometry>
      <origin xyz="0.0 0.0 0.0" rpy="0.0 -0.0 0.0"/>
    </collision>
  </link>

  <link name="gimbal3_link">
    <inertial>
      <origin xyz="-0.00926567494919772 1.97039712329184e-06 0.0128616849753724" rpy="0.0 -0.0 0.0"/>
      <mass value="0.243868409767181"/>
      <inertia ixx="4.70366622152039e-05" ixy="-5.23334464430183e-09" ixz="-4.5851027019603e-07" iyy="4.49457729860046e-05" iyz="-2.62506744960961e-09" izz="4.59133399019854e-05"/>
      <!-- <origin xyz="-0.00926567494919739 1.97039727626326e-06 0.0128616849753725" rpy="0.0 -0.0 0.0"/> -->
      <!-- <mass value="0.243868409767181"/> -->
      <!-- <inertia ixx="4.70366622152039e-05" ixy="-5.23334464430207e-09" ixz="-4.58510270196014e-07" iyy="4.49457729860046e-05" iyz="-2.62506744960844e-09" izz="4.59133399019853e-05"/> -->
    </inertial>
    <visual>
      <geometry>
        <mesh filename="package://gimbalrotor/grape/meshes/gimbal3_link.dae"/>
      </geometry>
      <material name="__unnamed_material_6"/>
      <origin xyz="0.0 0.0 0.0" rpy="0.0 -0.0 0.0"/>
    </visual>
    <collision>
      <geometry>
        <mesh filename="package://gimbalrotor/grape/meshes/gimbal3_link.stl"/>
      </geometry>
      <origin xyz="0.0 0.0 0.0" rpy="0.0 -0.0 0.0"/>
    </collision>
  </link>

  <link name="thrust3">
    <inertial>
      <origin xyz="-5.83425141531535e-09 6.01800406659052e-10 0.00419839092622981" rpy="0.0 -0.0 0.0"/>
      <mass value="0.0113797986875362"/>
      <inertia ixx="8.74001997906142e-05" ixy="-4.12766506892759e-06" ixz="-1.9423641282498e-13" iyy="6.72594264594888e-07" iyz="8.63468898765394e-15" izz="8.79093348579925e-05"/>
    </inertial>
    <visual>
      <geometry>
        <mesh filename="package://gimbalrotor/grape/meshes/thrust3.dae"/>
      </geometry>
      <material name="__unnamed_material_7"/>
      <origin xyz="0.0 0.0 0.0" rpy="0.0 -0.0 0.0"/>
    </visual>
    <collision>
      <geometry>
        <mesh filename="package://gimbalrotor/grape/meshes/thrust3.stl"/>
      </geometry>
      <origin xyz="0.0 0.0 0.0" rpy="0.0 -0.0 0.0"/>
    </collision>
  </link>

  <link name="gimbal4_link">
    <inertial>
      <origin xyz="-0.00926567494919772 1.97039712329184e-06 0.0128616849753724" rpy="0.0 -0.0 0.0"/>
      <mass value="0.243868409767181"/>
      <inertia ixx="4.70366622152039e-05" ixy="-5.23334464430183e-09" ixz="-4.5851027019603e-07" iyy="4.49457729860046e-05" iyz="-2.62506744960961e-09" izz="4.59133399019854e-05"/>
      <!-- <origin xyz="-0.00926567494919772 1.97039712329184e-06 0.0128616849753724" rpy="0.0 -0.0 0.0"/> -->
      <!-- <mass value="0.243868409767181"/> -->
      <!-- <inertia ixx="4.70366622152039e-05" ixy="-5.23334464430183e-09" ixz="-4.5851027019603e-07" iyy="4.49457729860046e-05" iyz="-2.62506744960961e-09" izz="4.59133399019854e-05"/> -->
    </inertial>
    <visual>
      <geometry>
        <mesh filename="package://gimbalrotor/grape/meshes/gimbal4_link.dae"/>
      </geometry>
      <material name="__unnamed_material_8"/>
      <origin xyz="0.0 0.0 0.0" rpy="0.0 -0.0 0.0"/>
    </visual>
    <collision>
      <geometry>
        <mesh filename="package://gimbalrotor/grape/meshes/gimbal4_link.stl"/>
      </geometry>
      <origin xyz="0.0 0.0 0.0" rpy="0.0 -0.0 0.0"/>
    </collision>
  </link>

  <link name="thrust4">
    <inertial>
      <origin xyz="-2.5501448175369e-09 3.18832430420899e-09 0.00419843814009516" rpy="0.0 -0.0 0.0"/>
      <mass value="0.0113800667770834"/>
      <inertia ixx="8.73993574510469e-05" ixy="4.12756894375054e-06" ixz="-1.15301708553968e-13" iyy="6.7258088604331e-07" iyz="1.31787422616219e-13" izz="8.79084828126607e-05"/>
    </inertial>
    <visual>
      <geometry>
        <mesh filename="package://gimbalrotor/grape/meshes/thrust4.dae"/>
      </geometry>
      <material name="__unnamed_material_9"/>
      <origin xyz="0.0 0.0 0.0" rpy="0.0 -0.0 0.0"/>
    </visual>
    <collision>
      <geometry>
        <mesh filename="package://gimbalrotor/grape/meshes/thrust4.stl"/>
      </geometry>
      <origin xyz="0.0 0.0 0.0" rpy="0.0 -0.0 0.0"/>
    </collision>
  </link>

  <joint name="gimbal1" type="revolute">
    <limit effort="0.0" velocity="0.0" lower="-3.14" upper="3.14"/>
    <parent link="main_body"/>
    <child link="gimbal1_link"/>
    <axis xyz="1. 0. 0."/>
    <origin xyz="-0.22309 -0.22309 0.0" rpy="0.0 -0.0 -2.3562"/>
  </joint>

  <joint name="rotor1" type="continuous">
    <limit effort="0.0" velocity="0.0"/>
    <parent link="gimbal1_link"/>
    <child link="thrust1"/>
    <axis xyz=" 0.  0. -1."/>
    <origin xyz="0.0 0.0 0.0585" rpy="0.0 -0.0 0.0"/>
  </joint>

  <joint name="gimbal2" type="revolute">
    <limit effort="0.0" velocity="0.0" lower="-3.14" upper="3.14"/>
    <parent link="main_body"/>
    <child link="gimbal2_link"/>
    <axis xyz="1. 0. 0."/>
    <origin xyz="0.22309 -0.22309 0.0" rpy="-0.0 -0.0 -0.7854000000000001"/>
  </joint>

  <joint name="rotor2" type="continuous">
    <limit effort="0.0" velocity="0.0"/>
    <parent link="gimbal2_link"/>
    <child link="thrust2"/>
    <axis xyz="0. 0. 1."/>
    <origin xyz="0.0 0.0 0.0585" rpy="0.0 -0.0 0.0"/>
  </joint>

  <joint name="gimbal3" type="revolute">
    <limit effort="0.0" velocity="0.0" lower="-3.14" upper="3.14"/>
    <parent link="main_body"/>
    <child link="gimbal3_link"/>
    <axis xyz="1. 0. 0."/>
    <origin xyz="0.22309 0.22309 0.0" rpy="0.0 -0.0 0.7854000000000001"/>
  </joint>

  <joint name="rotor3" type="continuous">
    <limit effort="0.0" velocity="0.0"/>
    <parent link="gimbal3_link"/>
    <child link="thrust3"/>
    <axis xyz=" 0.  0. -1."/>
    <origin xyz="0.0 0.0 0.0585" rpy="0.0 -0.0 0.0"/>
  </joint>

  <joint name="gimbal4" type="revolute">
    <limit effort="0.0" velocity="0.0" lower="-3.14" upper="3.14"/>
    <parent link="main_body"/>
    <child link="gimbal4_link"/>
    <axis xyz="1. 0. 0."/>
    <origin xyz="-0.22309 0.22309 0.0" rpy="0.0 -0.0 2.3562"/>
  </joint>

  <joint name="rotor4" type="continuous">
    <limit effort="0.0" velocity="0.0"/>
    <parent link="gimbal4_link"/>
    <child link="thrust4"/>
    <axis xyz="0. 0. 1."/>
    <origin xyz="0.0 0.0 0.0585" rpy="0.0 -0.0 0.0"/>
  </joint>

  <material name="__unnamed_material_1">
    <color rgba="0.10980392 0.10980392 0.10980392 1.        "/>
  </material>
  <material name="__unnamed_material_2">
    <color rgba="0.75294118 0.75294118 0.75294118 1.        "/>
  </material>
  <material name="__unnamed_material_3">
    <color rgba="0.50196078 0.50196078 0.50196078 1.        "/>
  </material>
  <material name="__unnamed_material_4">
    <color rgba="0.89803922 0.91764706 0.92941176 1.        "/>
  </material>
  <material name="__unnamed_material_5">
    <color rgba="0.50196078 0.50196078 0.50196078 1.        "/>
  </material>
  <material name="__unnamed_material_6">
    <color rgba="0.75294118 0.75294118 0.75294118 1.        "/>
  </material>
  <material name="__unnamed_material_7">
    <color rgba="0.50196078 0.50196078 0.50196078 1.        "/>
  </material>
  <material name="__unnamed_material_8">
    <color rgba="0.89803922 0.91764706 0.92941176 1.        "/>
  </material>
  <material name="__unnamed_material_9">
    <color rgba="0.50196078 0.50196078 0.50196078 1.        "/>
  </material>

</robot>
