<?xml version="1.0" ?>
<!-- =================================================================================== -->
<!-- |    This document was autogenerated by xacro from robot.urdf.xacro               | -->
<!-- |    EDITING THIS FILE BY HAND IS NOT RECOMMENDED                                 | -->
<!-- =================================================================================== -->
<robot name="module_quadrotor">
  <!-- general attribute -->
  <baselink name="fc"/>
  <thrust_link name="thrust"/>
  <!-- dynamics -->
  <m_f_rate value="-0.011"/>
  <!-- [N] -->
  <!-- dummy root link for KDL -->
  <link name="root">
    <inertial>
      <origin rpy="0 0 0" xyz="0 0 0"/>
      <mass value="0.00001"/>
      <inertia ixx="0.000001" ixy="0.0" ixz="0.0" iyy="0.000001" iyz="0.0" izz="0.000002"/>
    </inertial>
  </link>
  <joint name="root_joint" type="fixed">
    <parent link="root"/>
    <child link="main_body"/>
    <origin rpy="0 0 0" xyz="0 0 0"/>
    <axis xyz="0 0 1"/>
  </joint>
  <!-- main_body -->
  <link name="main_body">
    <inertial>
      <mass value="0.832"/>
      <origin rpy="0 0 0" xyz="0.002 0 0.026000000000000002"/>
      <!-- TODO: true cog pos -->
      <inertia ixx="0.0030" ixy="0" ixz="0" iyy="0.0030" iyz="0" izz="0.0045"/>
    </inertial>
    <visual>
      <origin rpy="0 0 0" xyz="0 0 0"/>
      <geometry>
        <mesh filename="package://mini_quadrotor/urdf/mesh/main_body_livox.dae"/>
      </geometry>
    </visual>
    <collision>
      <origin rpy="0 0 0" xyz="0 0 0"/>
      <geometry>
        <box size="0.28 0.28 0.072"/>
      </geometry>
    </collision>
  </link>
  <joint name="main_body2fc" type="fixed">
    <parent link="main_body"/>
    <child link="fc"/>
    <origin rpy="0 0 0" xyz="0 0 0"/>
  </joint>
  <link name="fc">
    <inertial>
      <mass value="00"/>
      <origin rpy="0 0 0" xyz="0 0 0"/>
      <inertia ixx="0.0" ixy="0.0" ixz="0.0" iyy="0.0" iyz="0.0" izz="0.0"/>
    </inertial>
  </link>
  <joint name="main_body2lidar_imu" type="fixed">
    <parent link="main_body"/>
    <child link="lidar_imu"/>
    <origin rpy="0 0 0" xyz="0.011 0.02329 0.04538"/>
  </joint>
  <link name="lidar_imu">
    <inertial>
      <mass value="00"/>
      <origin rpy="0 0 0" xyz="0 0 0"/>
      <inertia ixx="0.0" ixy="0.0" ixz="0.0" iyy="0.0" iyz="0.0" izz="0.0"/>
    </inertial>
  </link>
  <joint name="main_body2battery" type="fixed">
    <parent link="main_body"/>
    <child link="battery"/>
    <origin rpy="1.5707963267948966 0 0" xyz="0.0 0 -0.035"/>
  </joint>
  <link name="battery">
    <inertial>
      <mass value="0.188"/>
      <origin rpy="0 0 0" xyz="0 0 0"/>
      <inertia ixx="0.0002" ixy="0.0" ixz="0.0" iyy="0.0002" iyz="0.0" izz="0.0002"/>
    </inertial>
    <visual>
      <origin rpy="0 0 0" xyz="0 0 0"/>
      <geometry>
        <mesh filename="package://mini_quadrotor/urdf/mesh/turnigy_3S_2200mAh.dae" scale="1 1 1"/>
      </geometry>
    </visual>
  </link>
  <joint name="rotor1" type="revolute">
    <limit effort="100.0" lower="0.0" upper="8.0" velocity="0.5"/>
    <parent link="main_body"/>
    <child link="thrust1"/>
    <origin rpy="0 0 0" xyz="-0.085 -0.085 0.026"/>
    <axis xyz="0 0 -1"/>
  </joint>
  <link name="thrust1">
    <!-- visual & collisiont -->
    <inertial>
      <origin rpy="0 0 0" xyz="0 0 0"/>
      <mass value="0.0091"/>
      <inertia ixx="0.00000807" ixy="0.0" ixz="0.0" iyy="0.00000807" iyz="0.0" izz="0.00001612"/>
    </inertial>
    <visual>
      <origin rpy="0 0 0" xyz="0 0 0"/>
      <geometry>
        <mesh filename="package://mini_quadrotor/urdf/mesh/prop_5inch.dae"/>
      </geometry>
    </visual>
  </link>
  <gazebo reference="main_body">
    <dampingFactor>0.00</dampingFactor>
  </gazebo>
  <transmission name="rotor_tran1">
    <type>transmission_interface/SimpleTransmission</type>
    <joint name="rotor1">
      <!-- TODO: effort is torque, maybe position is enough -->
      <hardwareInterface>RotorInterface</hardwareInterface>
    </joint>
    <actuator name="rotor1">
      <!-- TODO: effort is torque, maybe position is enough -->
      <hardwareInterface>RotorInterface</hardwareInterface>
      <mechanicalReduction>1</mechanicalReduction>
    </actuator>
  </transmission>
  <joint name="rotor2" type="revolute">
    <limit effort="100.0" lower="0.0" upper="8.0" velocity="0.5"/>
    <parent link="main_body"/>
    <child link="thrust2"/>
    <origin rpy="0 0 0" xyz="0.085 -0.085 0.026"/>
    <axis xyz="0 0 1"/>
  </joint>
  <link name="thrust2">
    <!-- visual & collisiont -->
    <inertial>
      <origin rpy="0 0 0" xyz="0 0 0"/>
      <mass value="0.0091"/>
      <inertia ixx="0.00000807" ixy="0.0" ixz="0.0" iyy="0.00000807" iyz="0.0" izz="0.00001612"/>
    </inertial>
    <visual>
      <origin rpy="0 0 0" xyz="0 0 0"/>
      <geometry>
        <mesh filename="package://mini_quadrotor/urdf/mesh/prop_5inch.dae"/>
      </geometry>
    </visual>
  </link>
  <gazebo reference="main_body">
    <dampingFactor>0.00</dampingFactor>
  </gazebo>
  <transmission name="rotor_tran2">
    <type>transmission_interface/SimpleTransmission</type>
    <joint name="rotor2">
      <!-- TODO: effort is torque, maybe position is enough -->
      <hardwareInterface>RotorInterface</hardwareInterface>
    </joint>
    <actuator name="rotor2">
      <!-- TODO: effort is torque, maybe position is enough -->
      <hardwareInterface>RotorInterface</hardwareInterface>
      <mechanicalReduction>1</mechanicalReduction>
    </actuator>
  </transmission>
  <joint name="rotor3" type="revolute">
    <limit effort="100.0" lower="0.0" upper="8.0" velocity="0.5"/>
    <parent link="main_body"/>
    <child link="thrust3"/>
    <origin rpy="0 0 0" xyz="0.085 0.085 0.026"/>
    <axis xyz="0 0 -1"/>
  </joint>
  <link name="thrust3">
    <!-- visual & collisiont -->
    <inertial>
      <origin rpy="0 0 0" xyz="0 0 0"/>
      <mass value="0.0091"/>
      <inertia ixx="0.00000807" ixy="0.0" ixz="0.0" iyy="0.00000807" iyz="0.0" izz="0.00001612"/>
    </inertial>
    <visual>
      <origin rpy="0 0 0" xyz="0 0 0"/>
      <geometry>
        <mesh filename="package://mini_quadrotor/urdf/mesh/prop_5inch.dae"/>
      </geometry>
    </visual>
  </link>
  <gazebo reference="main_body">
    <dampingFactor>0.00</dampingFactor>
  </gazebo>
  <transmission name="rotor_tran3">
    <type>transmission_interface/SimpleTransmission</type>
    <joint name="rotor3">
      <!-- TODO: effort is torque, maybe position is enough -->
      <hardwareInterface>RotorInterface</hardwareInterface>
    </joint>
    <actuator name="rotor3">
      <!-- TODO: effort is torque, maybe position is enough -->
      <hardwareInterface>RotorInterface</hardwareInterface>
      <mechanicalReduction>1</mechanicalReduction>
    </actuator>
  </transmission>
  <joint name="rotor4" type="revolute">
    <limit effort="100.0" lower="0.0" upper="8.0" velocity="0.5"/>
    <parent link="main_body"/>
    <child link="thrust4"/>
    <origin rpy="0 0 0" xyz="-0.085 0.085 0.026"/>
    <axis xyz="0 0 1"/>
  </joint>
  <link name="thrust4">
    <!-- visual & collisiont -->
    <inertial>
      <origin rpy="0 0 0" xyz="0 0 0"/>
      <mass value="0.0091"/>
      <inertia ixx="0.00000807" ixy="0.0" ixz="0.0" iyy="0.00000807" iyz="0.0" izz="0.00001612"/>
    </inertial>
    <visual>
      <origin rpy="0 0 0" xyz="0 0 0"/>
      <geometry>
        <mesh filename="package://mini_quadrotor/urdf/mesh/prop_5inch.dae"/>
      </geometry>
    </visual>
  </link>
  <gazebo reference="main_body">
    <dampingFactor>0.00</dampingFactor>
  </gazebo>
  <transmission name="rotor_tran4">
    <type>transmission_interface/SimpleTransmission</type>
    <joint name="rotor4">
      <!-- TODO: effort is torque, maybe position is enough -->
      <hardwareInterface>RotorInterface</hardwareInterface>
    </joint>
    <actuator name="rotor4">
      <!-- TODO: effort is torque, maybe position is enough -->
      <hardwareInterface>RotorInterface</hardwareInterface>
      <mechanicalReduction>1</mechanicalReduction>
    </actuator>
  </transmission>
</robot>

