<?xml version="1.0"?>
<robot
    xmlns:xacro="http://www.ros.org/wiki/xacro" name="hydrus" >

  <!-- basic kinematics model -->
  <xacro:include filename="$(find hydrus)/urdf/common.xacro" />
  <xacro:include filename="$(find hydrus)/urdf/link.urdf.xacro" />

  <xacro:hydrus_link links="4" self="1" rotor_direction="-1" with_battery = "0" tilt_mode="1" tilt_angle="10" prop_15inch="1"/>
  <xacro:hydrus_link links="4" self="2" rotor_direction="1"  with_battery = "0" tilt_mode="1" tilt_angle="10" prop_15inch="1"/>
  <xacro:hydrus_link links="4" self="3" rotor_direction="-1" with_battery = "0" tilt_mode="1" tilt_angle="10" prop_15inch="1"/>
  <xacro:hydrus_link links="4" self="4" rotor_direction="1"  with_battery = "0" tilt_mode="1" tilt_angle="10" prop_15inch="1"/>

  <!-- onboard -->
  <!-- 1.  processor -->
  <!-- 1.1 flight controller -->
  <xacro:extra_module name = "fc" parent = "link3" visible = "1"
                      model_url = "package://hydrus/urdf/mesh/ver2/flight_controller/spinal.dae"> <!-- same with intel euclid -->
    <origin xyz="0.05 0 -0.02" rpy="0 0 0"/>
    <inertial>
      <mass value = "0.05" />
      <origin xyz="${13*0.001} ${4.4*0.001} ${-9*0.001}" rpy="0 0 0"/>
      <inertia
          ixx="0.00001" ixy="0.0" ixz="0.0"
          iyy="0.00001" iyz="0.0"
          izz="0.00002"/>
    </inertial>
  </xacro:extra_module>
  <!-- end: flight controller -->

  <!-- 1.2 processor: jetson tx2 -->
  <!-- confirm the inertial parameter with real machine -->
  <xacro:extra_module name = "pc" parent = "link3" visible = "1"
                      model_url = "package://hydrus/urdf/mesh/ver2/processor/jetson_tx2_unit.dae" >
    <origin xyz="0.05 0 -0.05" rpy="0 0 0"/>
    <inertial>
      <mass value = "0.181" />
      <origin xyz="${18 * 0.001} ${4 * 0.001} ${-18 * 0.001}" rpy="0 0 0"/>
      <inertia
          ixx="0.00007" ixy="0.0" ixz="0.0"
          iyy="0.00003" iyz="0.0"
          izz="0.00009"/>
    </inertial>
  </xacro:extra_module>
  <!-- end: processor: jetson tx2 -->

  <!-- 2.  sensor -->
  <!-- 2.1 livox mid360 -->
  <xacro:extra_module name = "lidar_imu" parent = "link3" visible = "0" > <!-- should be IMU frame -->
    <origin xyz="0.05 0 0.05" rpy="0 0 0"/> <!-- TODO: the true pos -->
    <inertial>
      <mass value = "0.2" />
      <origin xyz="0 0 0" rpy="0 0 0"/>
      <inertia
          ixx="0.0" ixy="0.0" ixz="0.0"
          iyy="0.0" iyz="0.0" izz="0.0"/>
    </inertial>
  </xacro:extra_module>

  <!-- 3 tail -->
  <link name="tail_link1"/>
  <link name="tail_link2"/>
  <link name="tail_link3"/>
  <link name="tail_link4"/>
  <link name="tail_link5"/>

  <joint name="tail_joint1" type="revolute">
    <limit effort="10.0" lower="${-pi/2}" upper="${pi/2}" velocity="0.5"/>
    <parent link="link4"/>
    <child link="tail_link1"/>
    <origin xyz="0 0 0.5" rpy="0 0 0"/>
    <axis xyz="0 0 1"/>
    <dynamics damping="0.9" friction="0.05"/>
  </joint>

  <joint name="tail_joint2" type="revolute">
    <limit effort="10.0" lower="${-pi/2}" upper="${pi/2}" velocity="0.5"/>
    <parent link="tail_link1"/>
    <child link="tail_link2"/>
    <origin xyz="0 0 0" rpy="0 0 0"/>
    <axis xyz="0 0 1"/>
    <dynamics damping="0.9" friction="0.05"/>
  </joint>

  <joint name="tail_joint3" type="revolute">
    <limit effort="10.0" lower="${-pi/2}" upper="${pi/2}" velocity="0.5"/>
    <parent link="tail_link2"/>
    <child link="tail_link3"/>
    <origin xyz="0 0 0" rpy="0 0 0"/>
    <axis xyz="0 0 1"/>
    <dynamics damping="0.9" friction="0.05"/>
  </joint>

  <joint name="tail_joint4" type="revolute">
    <limit effort="10.0" lower="${-pi/2}" upper="${pi/2}" velocity="0.5"/>
    <parent link="tail_link3"/>
    <child link="tail_link4"/>
    <origin xyz="0 0 0" rpy="0 0 0"/>
    <axis xyz="0 0 1"/>
    <dynamics damping="0.9" friction="0.05"/>
  </joint>

  <joint name="tail_joint5" type="revolute">
    <limit effort="10.0" lower="${-pi/2}" upper="${pi/2}" velocity="0.5"/>
    <parent link="tail_link4"/>
    <child link="tail_link5"/>
    <origin xyz="0 0 0" rpy="0 0 0"/>
    <axis xyz="0 0 1"/>
    <dynamics damping="0.9" friction="0.05"/>
  </joint>


</robot>
