<?xml version="1.0" ?>
<!-- =================================================================================== -->
<!-- |    This document was autogenerated by xacro from rolling.urdf.xacro             | -->
<!-- |    EDITING THIS FILE BY HAND IS NOT RECOMMENDED                                 | -->
<!-- =================================================================================== -->
<robot name="rolling">
  <!-- general attribute -->
  <baselink name="fc"/>
  <thrust_link name="thrust"/>
  <m_f_rate value="-0.0172"/>
  <!-- [N] -->

  <mujoco>
    <compiler discardvisual="true" meshdir="mesh"/>
  </mujoco>
  
    ### link ###
    
  <link name="link1">
    <inertial>
      <origin rpy="0 0 0" xyz="0.27537173 -0.03961308 -0.00327255"/>
      <mass value="0.49664453"/>
      <inertia ixx="0.00358710" ixy="0.00006483" ixz="0.00207127" iyy="0.02132702" iyz="0.00033016" izz="0.02325324"/>
    </inertial>
    <collision>
      <origin rpy="0 0 0" xyz="0 0 0"/>
      <geometry>
        <mesh filename="link.STL" scale="0.001 0.001 0.001"/>
      </geometry>
      <material name="glay">
        <color rgba="0.5 0.5 0.5 1.0"/>
      </material>
    </collision>
    <!-- <collision> -->
    <!--   <origin xyz="0.225 0 0" rpy="0 0 0" /> -->
    <!--   <geometry> -->
    <!--     <box size="0.6135 0.052 0.15" /> -->
    <!--   </geometry> -->
    <!-- </collision> -->
  </link>
  
    ### link1 ###
    
  <gazebo reference="link1">
    <mu1>0.4</mu1>
    <mu2>0.4</mu2>
  </gazebo>
  <link name="root">
    <inertial>
      <origin rpy="0 0 0" xyz="0 0 0"/>
      <mass value="0.00001"/>
      <inertia ixx="0.000001" ixy="0.0" ixz="0.0" iyy="0.000001" iyz="0.0" izz="0.000001"/>
    </inertial>
  </link>
  <joint name="root_joint" type="fixed">
    <parent link="root"/>
    <child link="link1"/>
    <origin rpy="0 0 0" xyz="0 0 0"/>
    <axis xyz="0 0 1"/>
  </joint>
  <!-- gimbal  -->
  <link name="gimbal_link1">
    <inertial>
      <origin rpy="0 0 0" xyz="0.00821058 -0.00000236 0.00688663"/>
      <mass value="0.26319459"/>
      <inertia ixx="0.00067258" ixy="0.00000001" ixz="-0.00013588" iyy="0.00073909" iyz="0.00000004" izz="0.00025874"/>
    </inertial>
    <collision>
      <origin rpy="0 0.1 0" xyz="0 0 0"/>
      <geometry>
        <mesh filename="roll_gimbal_module.STL" scale="0.001 0.001 0.001"/>
      </geometry>
      <material name="black">
        <color rgba="0 0 0 1.0"/>
      </material>
    </collision>
    <!-- <collision> -->
    <!--   <origin rpy="0 0.1 0" xyz="0 0 0.05"/> -->
    <!--   <geometry> -->
    <!--     <cylinder length="0.05" radius="0.1"/> -->
    <!--   </geometry> -->
    <!-- </collision> -->
  </link>
  

    ### joints ###
    #### link joint ####
    
  <joint name="joint1" type="revolute">
    <limit effort="10.0" lower="-3.141592653589793" upper="3.141592653589793" velocity="0.1"/>
    <origin rpy="0 0 0" xyz="0.52477 0 0"/>
    <parent link="link1"/>
    <child link="link2"/>
    <axis xyz="0 0 1"/>
    <dynamics damping="0.9" friction="0.05"/>
  </joint>
  

    #### gimbal joint ####
    
  <joint name="gimbal1" type="continuous">
    <limit effort="3" lower="-3.14" upper="3.14" velocity="12.5"/>
    <parent link="link1"/>
    <child link="gimbal_link1"/>
    <origin rpy="0 0 0" xyz="0.1935 0 0"/>
    <axis xyz="1 0 0"/>
    <dynamics damping="0.1" friction="0.0"/>
  </joint>
  

    #### rotor coord link (virtual) ####
    
  <link name="rotor_coord1">
    <inertial>
      <origin rpy="0 0 0" xyz="0 0 0"/>
      <mass value="0.00001"/>
      <inertia ixx="0.000001" ixy="0.0" ixz="0.0" iyy="0.000001" iyz="0.0" izz="0.000001"/>
    </inertial>
  </link>
  

    #### rotor parent link (virtual) ####
    
  <link name="rotor_parent1">
    <inertial>
      <origin rpy="0 0 0" xyz="0 0 0"/>
      <mass value="0.00001"/>
      <inertia ixx="0.000001" ixy="0.0" ixz="0.0" iyy="0.000001" iyz="0.0" izz="0.000001"/>
    </inertial>
  </link>
  

    #### thrust link (virtual) ####
    
  <link name="thrust1">
    <inertial>
      <origin rpy="0 0 0" xyz="0 0 0"/>
      <mass value="0.00001"/>
      <inertia ixx="0.000001" ixy="0.0" ixz="0.0" iyy="0.000001" iyz="0.0" izz="0.000001"/>
    </inertial>
  </link>
  <gazebo reference="thrust1">
    <dampingFactor>0.00</dampingFactor>
  </gazebo>
  

    #### rotor coord link joint (virtual) ####
    
  <joint name="rotor_coord_link_joint1" type="fixed">
    <parent link="link1"/>
    <child link="rotor_coord1"/>
    <origin rpy="0 0.1 0" xyz="0.3 0 0"/>
    <axis xyz="0 0 1"/>
  </joint>
  

    #### rotor parent link joint (virtual) ####
    
  <joint name="rotor_parent_link_joint1" type="fixed">
    <parent link="gimbal_link1"/>
    <child link="rotor_parent1"/>
    <origin rpy="0 0.1 0" xyz="0 0 0.05"/>
     # TODO: update rotor position
      
    <axis xyz="0 0 1"/>
  </joint>
  

    #### rotor joint (virtual) ####
    
  <joint name="rotor1" type="continuous">
    <limit effort="100.0" lower="0.0" upper="18.0" velocity="0.5"/>
    <parent link="rotor_parent1"/>
    <child link="thrust1"/>
    <origin rpy="0 0 0" xyz="0 0 0"/>
    <axis xyz="0 0 1"/>
  </joint>
  

    #### hardware interface ####
    
  <transmission name="joint_tran1">
    <type>transmission_interface/SimpleTransmission</type>
    <joint name="joint1">
      <hardwareInterface>hardware_interface/EffortJointInterface</hardwareInterface>
    </joint>
    <actuator name="servo1">
      <hardwareInterface>hardware_interface/EffortJointInterface</hardwareInterface>
      <mechanicalReduction>1</mechanicalReduction>
    </actuator>
  </transmission>
  <transmission name="gimbal_tran1">
    <type>transmission_interface/SimpleTransmission</type>
    <joint name="gimbal1">
      <hardwareInterface>hardware_interface/EffortJointInterface</hardwareInterface>
    </joint>
    <actuator name="gimbal_servo1">
      <hardwareInterface>hardware_interface/EffortJointInterface</hardwareInterface>
      <mechanicalReduction>1</mechanicalReduction>
    </actuator>
  </transmission>
  <transmission name="rotor1_tran">
    <type>transmission_interface/SimpleTransmission</type>
    <joint name="rotor1">
      <hardwareInterface>RotorInterface</hardwareInterface>
    </joint>
    <actuator name="rotor1">
      <hardwareInterface>RotorInterface</hardwareInterface>
      <mechanicalReduction>1</mechanicalReduction>
    </actuator>
  </transmission>
  
    ### link ###
    
  <link name="link2">
    <inertial>
      <origin rpy="0 0 0" xyz="0.27537173 -0.03961308 -0.00327255"/>
      <mass value="0.49664453"/>
      <inertia ixx="0.00358710" ixy="0.00006483" ixz="0.00207127" iyy="0.02132702" iyz="0.00033016" izz="0.02325324"/>
    </inertial>
    <collision>
      <origin rpy="0 0 0" xyz="0 0 0"/>
      <geometry>
        <mesh filename="link.STL" scale="0.001 0.001 0.001"/>
      </geometry>
      <material name="glay">
        <color rgba="0.5 0.5 0.5 1.0"/>
      </material>
    </collision>
    <!-- <collision> -->
    <!--   <origin xyz="0.225 0 0" rpy="0 0 0" /> -->
    <!--   <geometry> -->
    <!--     <box size="0.6135 0.052 0.15" /> -->
    <!--   </geometry> -->
    <!-- </collision> -->
  </link>
  
    ### link2 ###
    
  <gazebo reference="link2">
    <mu1>0.4</mu1>
    <mu2>0.4</mu2>
  </gazebo>
  <link name="cylinder_collision">
    <inertial>
      <origin rpy="0 0 0" xyz="0 0 0"/>
      <mass value="0.00001"/>
      <inertia ixx="0.000001" ixy="0.0" ixz="0.0" iyy="0.000001" iyz="0.0" izz="0.000001"/>
    </inertial>
    <!-- <collision> -->
    <!--   <geometry> -->
    <!--     <cylinder length="0.03" radius="0.4"/> -->
    <!--   </geometry> -->
    <!-- </collision> -->
  </link>
  <joint name="cylinder_collision_joint" type="fixed">
    <parent link="link2"/>
    <child link="cylinder_collision"/>
    <origin rpy="0 0 0" xyz="0.262 0.153 0"/>
    <axis xyz="0 0 1"/>
  </joint>
  <gazebo reference="cylinder_collision">
    <mu1>1.5</mu1>
    <mu2>1.5</mu2>
  </gazebo>
  <link name="fc">
    <inertial>
      <origin rpy="0 0 0" xyz="0 0 0"/>
      <mass value="0.00001"/>
      <inertia ixx="0.000001" ixy="0.0" ixz="0.0" iyy="0.000001" iyz="0.0" izz="0.000002"/>
    </inertial>
  </link>
  <joint name="fc_joint" type="fixed">
    <child link="fc"/>
    <parent link="link2"/>
    <origin rpy="0 0 0" xyz="0 0 0"/>
    <axis xyz="0 0 1"/>
  </joint>
  <!-- gimbal  -->
  <link name="gimbal_link2">
    <inertial>
      <origin rpy="0 0 0" xyz="0.00821058 -0.00000236 0.00688663"/>
      <mass value="0.26319459"/>
      <inertia ixx="0.00067258" ixy="0.00000001" ixz="-0.00013588" iyy="0.00073909" iyz="0.00000004" izz="0.00025874"/>
    </inertial>
    <collision>
      <origin rpy="0 -0.1 0" xyz="0 0 0"/>
      <geometry>
        <mesh filename="roll_gimbal_module.STL" scale="0.001 0.001 0.001"/>
      </geometry>
      <material name="black">
        <color rgba="0 0 0 1.0"/>
      </material>
    </collision>
    <!-- <collision> -->
    <!--   <origin rpy="0 -0.1 0" xyz="0 0 0.05"/> -->
    <!--   <geometry> -->
    <!--     <cylinder length="0.05" radius="0.1"/> -->
    <!--   </geometry> -->
    <!-- </collision> -->
  </link>
  

    ### joints ###
    #### link joint ####
    
  <joint name="joint2" type="revolute">
    <limit effort="10.0" lower="-3.141592653589793" upper="3.141592653589793" velocity="0.1"/>
    <origin rpy="0 0 0" xyz="0.52477 0 0"/>
    <parent link="link2"/>
    <child link="link3"/>
    <axis xyz="0 0 1"/>
    <dynamics damping="0.9" friction="0.05"/>
  </joint>
  

    #### gimbal joint ####
    
  <joint name="gimbal2" type="continuous">
    <limit effort="3" lower="-3.14" upper="3.14" velocity="12.5"/>
    <parent link="link2"/>
    <child link="gimbal_link2"/>
    <origin rpy="0 0 0" xyz="0.1935 0 0"/>
    <axis xyz="1 0 0"/>
    <dynamics damping="0.1" friction="0.0"/>
  </joint>
  

    #### rotor coord link (virtual) ####
    
  <link name="rotor_coord2">
    <inertial>
      <origin rpy="0 0 0" xyz="0 0 0"/>
      <mass value="0.00001"/>
      <inertia ixx="0.000001" ixy="0.0" ixz="0.0" iyy="0.000001" iyz="0.0" izz="0.000001"/>
    </inertial>
  </link>
  

    #### rotor parent link (virtual) ####
    
  <link name="rotor_parent2">
    <inertial>
      <origin rpy="0 0 0" xyz="0 0 0"/>
      <mass value="0.00001"/>
      <inertia ixx="0.000001" ixy="0.0" ixz="0.0" iyy="0.000001" iyz="0.0" izz="0.000001"/>
    </inertial>
  </link>
  

    #### thrust link (virtual) ####
    
  <link name="thrust2">
    <inertial>
      <origin rpy="0 0 0" xyz="0 0 0"/>
      <mass value="0.00001"/>
      <inertia ixx="0.000001" ixy="0.0" ixz="0.0" iyy="0.000001" iyz="0.0" izz="0.000001"/>
    </inertial>
  </link>
  <gazebo reference="thrust2">
    <dampingFactor>0.00</dampingFactor>
  </gazebo>
  

    #### rotor coord link joint (virtual) ####
    
  <joint name="rotor_coord_link_joint2" type="fixed">
    <parent link="link2"/>
    <child link="rotor_coord2"/>
    <origin rpy="0 -0.1 0" xyz="0.3 0 0"/>
    <axis xyz="0 0 1"/>
  </joint>
  

    #### rotor parent link joint (virtual) ####
    
  <joint name="rotor_parent_link_joint2" type="fixed">
    <parent link="gimbal_link2"/>
    <child link="rotor_parent2"/>
    <origin rpy="0 -0.1 0" xyz="0 0 0.05"/>
     # TODO: update rotor position
      
    <axis xyz="0 0 1"/>
  </joint>
  

    #### rotor joint (virtual) ####
    
  <joint name="rotor2" type="continuous">
    <limit effort="100.0" lower="0.0" upper="18.0" velocity="0.5"/>
    <parent link="rotor_parent2"/>
    <child link="thrust2"/>
    <origin rpy="0 0 0" xyz="0 0 0"/>
    <axis xyz="0 0 -1"/>
  </joint>
  

    #### hardware interface ####
    
  <transmission name="joint_tran2">
    <type>transmission_interface/SimpleTransmission</type>
    <joint name="joint2">
      <hardwareInterface>hardware_interface/EffortJointInterface</hardwareInterface>
    </joint>
    <actuator name="servo2">
      <hardwareInterface>hardware_interface/EffortJointInterface</hardwareInterface>
      <mechanicalReduction>1</mechanicalReduction>
    </actuator>
  </transmission>
  <transmission name="gimbal_tran2">
    <type>transmission_interface/SimpleTransmission</type>
    <joint name="gimbal2">
      <hardwareInterface>hardware_interface/EffortJointInterface</hardwareInterface>
    </joint>
    <actuator name="gimbal_servo2">
      <hardwareInterface>hardware_interface/EffortJointInterface</hardwareInterface>
      <mechanicalReduction>1</mechanicalReduction>
    </actuator>
  </transmission>
  <transmission name="rotor2_tran">
    <type>transmission_interface/SimpleTransmission</type>
    <joint name="rotor2">
      <hardwareInterface>RotorInterface</hardwareInterface>
    </joint>
    <actuator name="rotor2">
      <hardwareInterface>RotorInterface</hardwareInterface>
      <mechanicalReduction>1</mechanicalReduction>
    </actuator>
  </transmission>
  
    ### link ###
    
  <link name="link3">
    <inertial>
      <origin rpy="0 0 0" xyz="0.27537173 -0.03961308 -0.00327255"/>
      <mass value="0.49664453"/>
      <inertia ixx="0.00358710" ixy="0.00006483" ixz="0.00207127" iyy="0.02132702" iyz="0.00033016" izz="0.02325324"/>
    </inertial>
    <collision>
      <origin rpy="0 0 0" xyz="0 0 0"/>
      <geometry>
        <mesh filename="link.STL" scale="0.001 0.001 0.001"/>
      </geometry>
      <material name="glay">
        <color rgba="0.5 0.5 0.5 1.0"/>
      </material>
    </collision>
    <!-- <collision> -->
    <!--   <origin xyz="0.225 0 0" rpy="0 0 0" /> -->
    <!--   <geometry> -->
    <!--     <box size="0.6135 0.052 0.15" /> -->
    <!--   </geometry> -->
    <!-- </collision> -->
  </link>
  
    ### link3 ###
    
  <gazebo reference="link3">
    <mu1>0.4</mu1>
    <mu2>0.4</mu2>
  </gazebo>
  <!-- gimbal  -->
  <link name="gimbal_link3">
    <inertial>
      <origin rpy="0 0 0" xyz="0.00821058 -0.00000236 0.00688663"/>
      <mass value="0.26319459"/>
      <inertia ixx="0.00067258" ixy="0.00000001" ixz="-0.00013588" iyy="0.00073909" iyz="0.00000004" izz="0.00025874"/>
    </inertial>
    <collision>
      <origin rpy="0 0.1 0" xyz="0 0 0"/>
      <geometry>
        <mesh filename="roll_gimbal_module.STL" scale="0.001 0.001 0.001"/>
      </geometry>
      <material name="black">
        <color rgba="0 0 0 1.0"/>
      </material>
    </collision>
    <!-- <collision> -->
    <!--   <origin rpy="0 0.1 0" xyz="0 0 0.05"/> -->
    <!--   <geometry> -->
    <!--     <cylinder length="0.05" radius="0.1"/> -->
    <!--   </geometry> -->
    <!-- </collision> -->
  </link>
  

    ### joints ###
    #### link joint ####
    
  

    #### gimbal joint ####
    
  <joint name="gimbal3" type="continuous">
    <limit effort="3" lower="-3.14" upper="3.14" velocity="12.5"/>
    <parent link="link3"/>
    <child link="gimbal_link3"/>
    <origin rpy="0 0 0" xyz="0.1935 0 0"/>
    <axis xyz="1 0 0"/>
    <dynamics damping="0.1" friction="0.0"/>
  </joint>
  

    #### rotor coord link (virtual) ####
    
  <link name="rotor_coord3">
    <inertial>
      <origin rpy="0 0 0" xyz="0 0 0"/>
      <mass value="0.00001"/>
      <inertia ixx="0.000001" ixy="0.0" ixz="0.0" iyy="0.000001" iyz="0.0" izz="0.000001"/>
    </inertial>
  </link>
  

    #### rotor parent link (virtual) ####
    
  <link name="rotor_parent3">
    <inertial>
      <origin rpy="0 0 0" xyz="0 0 0"/>
      <mass value="0.00001"/>
      <inertia ixx="0.000001" ixy="0.0" ixz="0.0" iyy="0.000001" iyz="0.0" izz="0.000001"/>
    </inertial>
  </link>
  

    #### thrust link (virtual) ####
    
  <link name="thrust3">
    <inertial>
      <origin rpy="0 0 0" xyz="0 0 0"/>
      <mass value="0.00001"/>
      <inertia ixx="0.000001" ixy="0.0" ixz="0.0" iyy="0.000001" iyz="0.0" izz="0.000001"/>
    </inertial>
  </link>
  <gazebo reference="thrust3">
    <dampingFactor>0.00</dampingFactor>
  </gazebo>
  

    #### rotor coord link joint (virtual) ####
    
  <joint name="rotor_coord_link_joint3" type="fixed">
    <parent link="link3"/>
    <child link="rotor_coord3"/>
    <origin rpy="0 0.1 0" xyz="0.3 0 0"/>
    <axis xyz="0 0 1"/>
  </joint>
  

    #### rotor parent link joint (virtual) ####
    
  <joint name="rotor_parent_link_joint3" type="fixed">
    <parent link="gimbal_link3"/>
    <child link="rotor_parent3"/>
    <origin rpy="0 0.1 0" xyz="0 0 0.05"/>
     # TODO: update rotor position
      
    <axis xyz="0 0 1"/>
  </joint>
  

    #### rotor joint (virtual) ####
    
  <joint name="rotor3" type="continuous">
    <limit effort="100.0" lower="0.0" upper="18.0" velocity="0.5"/>
    <parent link="rotor_parent3"/>
    <child link="thrust3"/>
    <origin rpy="0 0 0" xyz="0 0 0"/>
    <axis xyz="0 0 1"/>
  </joint>
  

    #### hardware interface ####
    
  <transmission name="gimbal_tran3">
    <type>transmission_interface/SimpleTransmission</type>
    <joint name="gimbal3">
      <hardwareInterface>hardware_interface/EffortJointInterface</hardwareInterface>
    </joint>
    <actuator name="gimbal_servo3">
      <hardwareInterface>hardware_interface/EffortJointInterface</hardwareInterface>
      <mechanicalReduction>1</mechanicalReduction>
    </actuator>
  </transmission>
  <transmission name="rotor3_tran">
    <type>transmission_interface/SimpleTransmission</type>
    <joint name="rotor3">
      <hardwareInterface>RotorInterface</hardwareInterface>
    </joint>
    <actuator name="rotor3">
      <hardwareInterface>RotorInterface</hardwareInterface>
      <mechanicalReduction>1</mechanicalReduction>
    </actuator>
  </transmission>
</robot>

